Workbook

Sheet 拳系マスタ
A1: 拳系CD | B1: 拳系
A2: 1 | B2: 仁王拳
A3: 2 | B3: 三合拳
A4: 3 | B4: 天王拳
A5: 4 | B5: 白蓮拳
A6: 5 | B6: 鶴立拳
A7: 6 | B7: 地王拳
A8: 7 | B8: 龍王拳
A9: 8 | B9: 龍華拳
A10: 9 | B10: 五花拳
A11: 10 | B11: 金剛拳
A12: 11 | B12: 羅漢拳

Sheet 階級マスタ
A1: 階級CD | B1: 階級
A2: 1 | B2: ⑥
A3: 2 | B3: ⑤
A4: 3 | B4: ④
A5: 4 | B5: ③
A6: 5 | B6: ②
A7: 6 | B7: ①
A8: 7 | B8: 初
A9: 8 | B9: 二
A10: 9 | B10: 三
A11: 10 | B11: 四
A12: 11 | B12: 五

Sheet 分類マスタ
A1: 分類CD | B1: 分類
A2: 1 | B2: 剛法
A3: 2 | B3: 柔法

Sheet 技リスト
A1: ID | B1: 拳系CD | C1: 拳系 | D1: 技名 | E1: 読み | F1: 階級CD | G1: 階級 | H1: 分類CD | I1: 分類 | J1: 構え | K1: 攻者構え | L1: 攻撃方法 | M1: 守者構え | N1: 守法 | O1: 教範頁 | P1: PDFファイル
A2: 1 | B2: 1 | C2: =VLOOKUP($B2,拳系マスタ!$A:$B,2,FALSE) -> 仁王拳 | D2: 流水蹴(後) | E2: りゅうすいげり うしろ | F2: 1 | G2: =VLOOKUP($F2,階級マスタ!$A:$B,2,FALSE) -> ⑥ | H2: 1 | I2: =VLOOKUP($H2,分類マスタ!$A:$B,2,FALSE) -> 剛法 | J2: 開 | K2: 左中段 | L2: 上段逆突 | M2: 右一字 | N2: 後流水・右手で高めの流水受け・順蹴 | O2: 170 | P2: 少林寺拳法教範(下巻抜粋)_170-171.pdf
A3: 2 | B3: 1 | C3: =VLOOKUP($B3,拳系マスタ!$A:$B,2,FALSE) -> 仁王拳 | D3: 流水蹴(前) | E3: りゅうすいげり まえ | F3: 2 | G3: =VLOOKUP($F3,階級マスタ!$A:$B,2,FALSE) -> ⑤ | H3: 1 | I3: =VLOOKUP($H3,分類マスタ!$A:$B,2,FALSE) -> 剛法 | J3: 対 | K3: 左中段 | L3: 上段逆突 | M3: 左一字 | N3: 前流水・右手で高めの流水受け・逆蹴 | O3: 170 | P3: 少林寺拳法教範(下巻抜粋)_170-171.pdf
A4: 3 | B4: 1 | C4: =VLOOKUP($B4,拳系マスタ!$A:$B,2,FALSE) -> 仁王拳 | D4: 転身蹴 | E4: てんしんげり | F4: 1 | G4: =VLOOKUP($F4,階級マスタ!$A:$B,2,FALSE) -> ⑥ | H4: 1 | I4: =VLOOKUP($H4,分類マスタ!$A:$B,2,FALSE) -> 剛法 | J4: 対 | K4: 左中段 | L4: 上段逆突 | M4: 左一字 | N4: やや後屈、左転身・右足逆蹴・順下りか蜘蛛足下り | O4: 176 | P4: 少林寺拳法教範(下巻抜粋)_176-177.pdf
A5: 4 | B5: 1 | C5: =VLOOKUP($B5,拳系マスタ!$A:$B,2,FALSE) -> 仁王拳 | D5: 内受突(裏) | E5: うちうけづき うら | F5: 1 | G5: =VLOOKUP($F5,階級マスタ!$A:$B,2,FALSE) -> ⑥ | H5: 1 | I5: =VLOOKUP($H5,分類マスタ!$A:$B,2,FALSE) -> 剛法 | J5: 対 | K5: 左中段 | L5: 上段逆突 | M5: 左一字 | N5: 左前千鳥・左手内受（そのまま頭を守る）・中段逆突・右足蹴込 | O5: 173 | P5: 少林寺拳法教範(下巻抜粋)_172-173.pdf
A6: 5 | B6: 1 | C6: =VLOOKUP($B6,拳系マスタ!$A:$B,2,FALSE) -> 仁王拳 | D6: 内受突(表) | E6: うちうけづき おもて | F6: 5 | G6: =VLOOKUP($F6,階級マスタ!$A:$B,2,FALSE) -> ② | H6: 1 | I6: =VLOOKUP($H6,分類マスタ!$A:$B,2,FALSE) -> 剛法 | J6: 開 | K6: 左中段 | L6: 上段逆突 | M6: 右一字 | N6: 右前千鳥・右手内受（そのまま頭を守る）・中段逆突 | O6: 173 | P6: 少林寺拳法教範(下巻抜粋)_172-173.pdf
A7: 6 | B7: 1 | C7: =VLOOKUP($B7,拳系マスタ!$A:$B,2,FALSE) -> 仁王拳 | D7: 内受蹴(表) | E7: うちうけげり おもて | F7: 4 | G7: =VLOOKUP($F7,階級マスタ!$A:$B,2,FALSE) -> ③ | H7: 1 | I7: =VLOOKUP($H7,分類マスタ!$A:$B,2,FALSE) -> 剛法 | J7: 開 | K7: 左中段 | L7: 上段逆突 | M7: 右一字 | N7: 内受（肩を回しながら前足を後足に寄せる）・順蹴足刀・踏込、右手刀 | O7: 174 | P7: 少林寺拳法教範(下巻抜粋)_174-175.pdf
A8: 7 | B8: 1 | C8: =VLOOKUP($B8,拳系マスタ!$A:$B,2,FALSE) -> 仁王拳 | D8: 内受蹴(裏) | E8: うちうけげり うら | F8: 4 | G8: =VLOOKUP($F8,階級マスタ!$A:$B,2,FALSE) -> ③ | H8: 1 | I8: =VLOOKUP($H8,分類マスタ!$A:$B,2,FALSE) -> 剛法 | J8: 対 | K8: 左中段 | L8: 上段逆突 | M8: 左一字 | N8: 内受（肩を回しながら前足を後足に寄せる）・順蹴足刀・踏込、右手刀 | O8: 174 | P8: 少林寺拳法教範(下巻抜粋)_174-175.pdf
A9: 8 | B9: 1 | C9: =VLOOKUP($B9,拳系マスタ!$A:$B,2,FALSE) -> 仁王拳 | D9: 上受突(表) | E9: うわうけづき おもて | F9: 1 | G9: =VLOOKUP($F9,階級マスタ!$A:$B,2,FALSE) -> ⑥ | H9: 1 | I9: =VLOOKUP($H9,分類マスタ!$A:$B,2,FALSE) -> 剛法 | J9: 対 | K9: 左中段 | L9: 逆手刀 | M9: 左一字 | N9: やや前屈、右転身・左手上受・右拳中段・左手熊手・右手で手払 | O9: 171 | P9: 少林寺拳法教範(下巻抜粋)_170-171.pdf
A10: 9 | B10: 1 | C10: =VLOOKUP($B10,拳系マスタ!$A:$B,2,FALSE) -> 仁王拳 | D10: 上受突(裏) | E10: うわうけづき うら | F10: 1 | G10: =VLOOKUP($F10,階級マスタ!$A:$B,2,FALSE) -> ⑥ | H10: 1 | I10: =VLOOKUP($H10,分類マスタ!$A:$B,2,FALSE) -> 剛法 | J10: 対 | K10: 左中段 | L10: 逆手刀 | M10: 左一字 | N10: やや前屈、左転身・右手上受・左拳中段・左手で手払 | O10: 171 | P10: 少林寺拳法教範(下巻抜粋)_170-171.pdf
A11: 10 | B11: 1 | C11: =VLOOKUP($B11,拳系マスタ!$A:$B,2,FALSE) -> 仁王拳 | D11: 上受蹴(表) | E11: うわうけげり おもて | F11: 2 | G11: =VLOOKUP($F11,階級マスタ!$A:$B,2,FALSE) -> ⑤ | H11: 1 | I11: =VLOOKUP($H11,分類マスタ!$A:$B,2,FALSE) -> 剛法 | J11: 対 | K11: 左中段 | L11: 逆手刀 | M11: 左一字 | N11: やや右足下がり左手上受・順蹴 | O11: 172 | P11: 少林寺拳法教範(下巻抜粋)_172-173.pdf
A12: 11 | B12: 1 | C12: =VLOOKUP($B12,拳系マスタ!$A:$B,2,FALSE) -> 仁王拳 | D12: 上受蹴(裏) | E12: うわうけげり うら | F12: 2 | G12: =VLOOKUP($F12,階級マスタ!$A:$B,2,FALSE) -> ⑤ | H12: 1 | I12: =VLOOKUP($H12,分類マスタ!$A:$B,2,FALSE) -> 剛法 | J12: 対 | K12: 左中段 | L12: 逆手刀 | M12: 左一字 | N12: 左転身・右手上受・右足逆蹴 | O12: 172 | P12: 少林寺拳法教範(下巻抜粋)_172-173.pdf
A13: 12 | B13: 1 | C13: =VLOOKUP($B13,拳系マスタ!$A:$B,2,FALSE) -> 仁王拳 | D13: 外受蹴 | E13: そとうけげり | F13: 3 | G13: =VLOOKUP($F13,階級マスタ!$A:$B,2,FALSE) -> ④ | H13: 1 | I13: =VLOOKUP($H13,分類マスタ!$A:$B,2,FALSE) -> 剛法 | J13: 対 | K13: 左中段 | L13: 上段逆突 | M13: 左一字 | N13: 左転身・逆足で蹴上（もしくは回し蹴） | O13: 175 | P13: 少林寺拳法教範(下巻抜粋)_174-175.pdf
... A19: 18 | B19: 1 | C19: =VLOOKUP($B19,拳系マスタ!$A:$B,2,FALSE) -> 仁王拳 | D19: 内押受突 | E19: うちおしうけづき | F19: 4 | G19: =VLOOKUP($F19,階級マスタ!$A:$B,2,FALSE) -> ③ | H19: 1 | I19: =VLOOKUP($H19,分類マスタ!$A:$B,2,FALSE) -> 剛法 | J19: 開 | K19: 左中段 | L19: 上段逆振突 | M19: 右一字 | N19: 内押受（肩を回しながら）・左手中段・右手熊手・左手で手払 | O19: 175 | P19: 少林寺拳法教範(下巻抜粋)_174-175.pdf
A20: 19 | B20: 1 | C20: =VLOOKUP($B20,拳系マスタ!$A:$B,2,FALSE) -> 仁王拳 | D20: 内押受蹴 | E20: うちおしうけげり | F20: 5 | G20: =VLOOKUP($F20,階級マスタ!$A:$B,2,FALSE) -> ② | H20: 1 | I20: =VLOOKUP($H20,分類マスタ!$A:$B,2,FALSE) -> 剛法 | J20: 開 | K20: 左中段 | L20: 上段逆振突 | M20: 右一字 | N20: 内押受（肩を回しながら前足を後足に寄せる）・順蹴足刀・踏込、右手刀
A21: 20 | B21: 1 | C21: =VLOOKUP($B21,拳系マスタ!$A:$B,2,FALSE) -> 仁王拳 | D21: 打上蹴 | E21: うちあげげり | F21: 3 | G21: =VLOOKUP($F21,階級マスタ!$A:$B,2,FALSE) -> ④ | H21: 1 | I21: =VLOOKUP($H21,分類マスタ!$A:$B,2,FALSE) -> 剛法 | J21: 開 | K21: 左中段 | L21: 上段逆突 | M21: 右一字 | N21: 後振身し、右拳握拳打上受、中段順蹴 | O21: 173 | P21: 少林寺拳法教範(下巻抜粋)_172-173.pdf
A22: 21 | B22: 1 | C22: =VLOOKUP($B22,拳系マスタ!$A:$B,2,FALSE) -> 仁王拳 | D22: 打上突 | E22: うちあげづき | F22: 3 | G22: =VLOOKUP($F22,階級マスタ!$A:$B,2,FALSE) -> ④ | H22: 1 | I22: =VLOOKUP($H22,分類マスタ!$A:$B,2,FALSE) -> 剛法 | J22: 対 | K22: 左中段 | L22: 上段逆突 | M22: 左一字 | N22: 右拳握拳打上受、左拳中段順突 | O22: 172 | P22: 少林寺拳法教範(下巻抜粋)_172-173.pdf
A23: 22 | B23: 1 | C23: =VLOOKUP($B23,拳系マスタ!$A:$B,2,FALSE) -> 仁王拳 | D23: 打上段突 | E23: うちあげだんづき | F23: 9 | G23: =VLOOKUP($F23,階級マスタ!$A:$B,2,FALSE) -> 三 | H23: 1 | I23: =VLOOKUP($H23,分類マスタ!$A:$B,2,FALSE) -> 剛法 | J23: 対 | K23: 左中段 | L23: 上段逆突 | M23: 左一字 | N23: 右拳握拳打上受し、直ちに右拳中段突 | O23: 178 | P23: 少林寺拳法教範(下巻抜粋)_178-179.pdf
A24: 23 | B24: 1 | C24: =VLOOKUP($B24,拳系マスタ!$A:$B,2,FALSE) -> 仁王拳 | D24: 屈身突 | E24: くっしんづき | F24: 5 | G24: =VLOOKUP($F24,階級マスタ!$A:$B,2,FALSE) -> ② | H24: 1 | I24: =VLOOKUP($H24,分類マスタ!$A:$B,2,FALSE) -> 剛法 | J24: 対 | K24: 左中段 | L24: 上段逆振突 | M24: 左一字 | N24: 屈伸・左打上受・攻者懐に入る・屈伸のまま右手中段突 | O24: 176 | P24: 少林寺拳法教範(下巻抜粋)_176-177.pdf
A25: 24 | B25: 1 | C25: =VLOOKUP($B25,拳系マスタ!$A:$B,2,FALSE) -> 仁王拳 | D25: 屈身蹴 | E25: くっしんげり | F25: 5 | G25: =VLOOKUP($F25,階級マスタ!$A:$B,2,FALSE) -> ② | H25: 1 | I25: =VLOOKUP($H25,分類マスタ!$A:$B,2,FALSE) -> 剛法 | J25: 対 | K25: 左中段 | L25: 上段逆振突 | M25: 左一字 | N25: 前足を左外に開き・屈伸・左打上受・右手下受・右足で回蹴 | O25: 176 | P25: 少林寺拳法教範(下巻抜粋)_176-177.pdf
A26: 25 | B26: 1 | C26: =VLOOKUP($B26,拳系マスタ!$A:$B,2,FALSE) -> 仁王拳 | D26: 屈身突蹴 | E26: くっしんづきげり | F26: 5 | G26: =VLOOKUP($F26,階級マスタ!$A:$B,2,FALSE) -> ② | H26: 1 | I26: =VLOOKUP($H26,分類マスタ!$A:$B,2,FALSE) -> 剛法 | J26: 対 | K26: 左中段 | L26: 上段逆振突 | M26: 左一字 | N26: 屈伸・左打上受・攻者懐に入る・屈伸のまま右手中段突・復位しながら右足で回蹴
A27: 26 | B27: 1 | C27: =VLOOKUP($B27,拳系マスタ!$A:$B,2,FALSE) -> 仁王拳 | D27: 開身突(表) | E27: かいしんづき おもて | F27: 8 | G27: =VLOOKUP($F27,階級マスタ!$A:$B,2,FALSE) -> 二 | H27: 1 | I27: =VLOOKUP($H27,分類マスタ!$A:$B,2,FALSE) -> 剛法 | J27: 開 | K27: 左中段 | L27: 上段逆突 | M27: 右乱 | N27: 開身・左手半月受・右拳上段突（・左拳中段突・右拳上段突・右足順蹴） | O27: 176 | P27: 少林寺拳法教範(下巻抜粋)_176-177.pdf
A28: 27 | B28: 1 | C28: =VLOOKUP($B28,拳系マスタ!$A:$B,2,FALSE) -> 仁王拳 | D28: 開身突(裏) | E28: かいしんづき うら | F28: 8 | G28: =VLOOKUP($F28,階級マスタ!$A:$B,2,FALSE) -> 二 | H28: 1 | I28: =VLOOKUP($H28,分類マスタ!$A:$B,2,FALSE) -> 剛法 | J28: 対 | K28: 左中段 | L28: 上段逆突 | M28: 左乱 | N28: 開身・右手半月受・左拳上段突（・右拳中段突・右足逆蹴） | O28: 176 | P28: 少林寺拳法教範(下巻抜粋)_176-177.pdf
A29: 28 | B29: 1 | C29: =VLOOKUP($B29,拳系マスタ!$A:$B,2,FALSE) -> 仁王拳 | D29: 半月蹴 | E29: はんげつげり | F29: 8 | G29: =VLOOKUP($F29,階級マスタ!$A:$B,2,FALSE) -> 二 | H29: 1 | I29: =VLOOKUP($H29,分類マスタ!$A:$B,2,FALSE) -> 剛法 | J29: 対 | K29: 左中段 | L29: 上段逆突 | M29: 左乱 | N29: 開身・右手半月受・右足逆蹴 | O29: 177 | P29: 少林寺拳法教範(下巻抜粋)_176-177.pdf
A30: 29 | B30: 1 | C30: =VLOOKUP($B30,拳系マスタ!$A:$B,2,FALSE) -> 仁王拳 | D30: 下受突 | E30: したうけづき | F30: 9 | G30: =VLOOKUP($F30,階級マスタ!$A:$B,2,FALSE) -> 三 | H30: 1 | I30: =VLOOKUP($H30,分類マスタ!$A:$B,2,FALSE) -> 剛法 | J30: 対 | K30: 左一字 | L30: 中段逆突 | M30: 左八双 | N30: 左足左横に出し、左下受・右拳上段突 | O30: 177 | P30: 少林寺拳法教範(下巻抜粋)_176-177.pdf
A31: 30 | B31: 1 | C31: =VLOOKUP($B31,拳系マスタ!$A:$B,2,FALSE) -> 仁王拳 | D31: 下受段突 | E31: したうけだんづき | F31: 9 | G31: =VLOOKUP($F31,階級マスタ!$A:$B,2,FALSE) -> 三 | H31: 1 | I31: =VLOOKUP($H31,分類マスタ!$A:$B,2,FALSE) -> 剛法 | J31: 対 | K31: 左一字 | L31: 中段逆突 | M31: 左八双 | N31: 左足左横に出し、左下受し、直ちに左拳上段裏拳突 | O31: 177 | P31: 少林寺拳法教範(下巻抜粋)_176-177.pdf
A32: 31 | B32: 1 | C32: =VLOOKUP($B32,拳系マスタ!$A:$B,2,FALSE) -> 仁王拳 | D32: 短刀突込下受打落蹴 | E32: たんとうつきこみしたうけうちおとしげり | F32: 9 | G32: =VLOOKUP($F32,階級マスタ!$A:$B,2,FALSE) -> 三 | H32: 1 | I32: =VLOOKUP($H32,分類マスタ!$A:$B,2,FALSE) -> 剛法 | J32: 対 | K32: 左一字 | L32: 短刀で中段逆突 | M32: 左八双 | N32: 下受蹴の要領で、左下受・もう一方の手で短刀打落・右足逆蹴 | O32: 179 | P32: 少林寺拳法教範(下巻抜粋)_178-179.pdf
A33: 32 | B33: 1 | C33: =VLOOKUP($B33,拳系マスタ!$A:$B,2,FALSE) -> 仁王拳 | D33: 短刀振上流水蹴 | E33: たんとうふりあげりゅうすいげり | F33: 9 | G33: =VLOOKUP($F33,階級マスタ!$A:$B,2,FALSE) -> 三 | H33: 1 | I33: =VLOOKUP($H33,分類マスタ!$A:$B,2,FALSE) -> 剛法 | J33: 開 | K33: 左中段 | L33: 右手で短刀振り下ろし | M33: 右一字 | N33: 後流水蹴の要領で、流水受け・順蹴・十字足退
A34: 33 | B34: 2 | C34: =VLOOKUP($B34,拳系マスタ!$A:$B,2,FALSE) -> 三合拳 | D34: 下受蹴 | E34: したうけげり | F34: 2 | G34: =VLOOKUP($F34,階級マスタ!$A:$B,2,FALSE) -> ⑤ | H34: 1 | I34: =VLOOKUP($H34,分類マスタ!$A:$B,2,FALSE) -> 剛法 | J34: 対 | K34: 左一字 | L34: 右手中段逆突 | M34: 左八双 | N34: 左に転身・左手下受・右足逆蹴中段 | O34: 182 | P34: 少林寺拳法教範(下巻抜粋)_182-183.pdf
A35: 34 | B35: 2 | C35: =VLOOKUP($B35,拳系マスタ!$A:$B,2,FALSE) -> 三合拳 | D35: 下受順蹴 | E35: したうけじゅんげり | F35: 2 | G35: =VLOOKUP($F35,階級マスタ!$A:$B,2,FALSE) -> ⑤ | H35: 1 | I35: =VLOOKUP($H35,分類マスタ!$A:$B,2,FALSE) -> 剛法 | J35: 対 | K35: 左一字 | L35: 左手中段順突 | M35: 左八双 | N35: やや前屈、開気味に構える 右に転身・右下受・左足順蹴 | O35: 182 | P35: 少林寺拳法教範(下巻抜粋)_182-183.pdf
A36: 35 | B36: 2 | C36: =VLOOKUP($B36,拳系マスタ!$A:$B,2,FALSE) -> 三合拳 | D36: 十字受蹴 | E36: じゅうじうけげり | F36: 4 | G36: =VLOOKUP($F36,階級マスタ!$A:$B,2,FALSE) -> ③ | H36: 1 | I36: =VLOOKUP($H36,分類マスタ!$A:$B,2,FALSE) -> 剛法 | J36: 対 | K36: 右一字 | L36: 差込右足中段回蹴 | M36: 右一字 | N36: やや前屈・横十字受・前足引き足、そのまま蹴り返し | O36: 183 | P36: 少林寺拳法教範(下巻抜粋)_182-183.pdf
A37: 36 | B37: 2 | C37: =VLOOKUP($B37,拳系マスタ!$A:$B,2,FALSE) -> 三合拳 | D37: 横転身蹴 | E37: よこてんしんげり | F37: 5 | G37: =VLOOKUP($F37,階級マスタ!$A:$B,2,FALSE) -> ② | H37: 1 | I37: =VLOOKUP($H37,分類マスタ!$A:$B,2,FALSE) -> 剛法 | J37: 対 | K37: 左一字 | L37: 左足差込、右足中段逆蹴 | M37: 左中段 | N37: やや前屈、右に開気味に転身・左圧拳打払受・右外受・中段順蹴 | O37: 183 | P37: 少林寺拳法教範(下巻抜粋)_182-183.pdf
A38: 37 | B38: 2 | C38: =VLOOKUP($B38,拳系マスタ!$A:$B,2,FALSE) -> 三合拳 | D38: 半転身蹴 | E38: はんてんしんげり | F38: 5 | G38: =VLOOKUP($F38,階級マスタ!$A:$B,2,FALSE) -> ② | H38: 1 | I38: =VLOOKUP($H38,分類マスタ!$A:$B,2,FALSE) -> 剛法 | J38: 開 | K38: 右一字 | L38: 右足差込、左足中段逆蹴 | M38: 左中段 | N38: 右半転身・左拳圧拳打落（引込むごとく）・右拳外受・左順蹴 | O38: 183 | P38: 少林寺拳法教範(下巻抜粋)_182-183.pdf
A39: 38 | B39: 2 | C39: =VLOOKUP($B39,拳系マスタ!$A:$B,2,FALSE) -> 三合拳 | D39: 逆転身蹴 | E39: ぎゃくてんしんげり | F39: 7 | G39: =VLOOKUP($F39,階級マスタ!$A:$B,2,FALSE) -> 初 | H39: 1 | I39: =VLOOKUP($H39,分類マスタ!$A:$B,2,FALSE) -> 剛法 | J39: 開 | K39: 左一字 | L39: 差替中段順突 | M39: 右八双 | N39: 右足逆転身・左下受・左足廻蹴 | O39: 183 | P39: 少林寺拳法教範(下巻抜粋)_182-183.pdf
A40: 39 | B40: 2 | C40: =VLOOKUP($B40,拳系マスタ!$A:$B,2,FALSE) -> 三合拳 | D40: 払受蹴 | E40: はらいうけげり | F40: 6 | G40: =VLOOKUP($F40,階級マスタ!$A:$B,2,FALSE) -> ① | H40: 1 | I40: =VLOOKUP($H40,分類マスタ!$A:$B,2,FALSE) -> 剛法 | J40: 開 | K40: 左一字 | L40: 左差込廻蹴 | M40: 右一字 | N40: 右三枚誘い・右足を左足の前に右丁字に踏み入れ・右手払受・左直蹴 | O40: 180 | P40: 少林寺拳法教範(下巻抜粋)_180-181.pdf
A41: 40 | B41: 2 | C41: =VLOOKUP($B41,拳系マスタ!$A:$B,2,FALSE) -> 三合拳 | D41: 下段返 | E41: げだんがえし | F41: 7 | G41: =VLOOKUP($F41,階級マスタ!$A:$B,2,FALSE) -> 初 | H41: 1 | I41: =VLOOKUP($H41,分類マスタ!$A:$B,2,FALSE) -> 剛法 | J41: 開 | K41: 左一字 | L41: 左差込廻蹴 | M41: 右一字 | N41: 右三枚誘い・左足左横に出し、右手払受・右足直蹴 | O41: 180 | P41: 少林寺拳法教範(下巻抜粋)_180-181.pdf
A42: 41 | B42: 2 | C42: =VLOOKUP($B42,拳系マスタ!$A:$B,2,FALSE) -> 三合拳 | D42: 中段返 | E42: ちゅうだんがえし | F42: 7 | G42: =VLOOKUP($F42,階級マスタ!$A:$B,2,FALSE) -> 初 | H42: 1 | I42: =VLOOKUP($H42,分類マスタ!$A:$B,2,FALSE) -> 剛法 | J42: 開 | K42: 左一字 | L42: 左差込廻蹴 | M42: 左待機 | N42: 左足を右足前に引きつつ体捻しながら右手下受・右足直蹴 | O42: 180 | P42: 少林寺拳法教範(下巻抜粋)_180-181.pdf
A43: 42 | B43: 3 | C43: =VLOOKUP($B43,拳系マスタ!$A:$B,2,FALSE) -> 天王拳 | D43: 突天一 | E43: つきてんいち | F43: 4 | G43: =VLOOKUP($F43,階級マスタ!$A:$B,2,FALSE) -> ③ | H43: 1 | I43: =VLOOKUP($H43,分類マスタ!$A:$B,2,FALSE) -> 剛法 | J43: 開 | K43: 左中段 | L43: 左拳上段・右拳中段 | M43: 右一字 | N43: 左足後千鳥・右手上受、左手下受の連受・右足順蹴、蜘蛛足退 | O43: 185 | P43: 少林寺拳法教範(下巻抜粋)_184-185.pdf
A44: 43 | B44: 3 | C44: =VLOOKUP($B44,拳系マスタ!$A:$B,2,FALSE) -> 天王拳 | D44: 突天二 | E44: つきてんに | F44: 6 | G44: =VLOOKUP($F44,階級マスタ!$A:$B,2,FALSE) -> ① | H44: 1 | I44: =VLOOKUP($H44,分類マスタ!$A:$B,2,FALSE) -> 剛法 | J44: 開 | K44: 左中段 | L44: 左拳上段・右拳上段 | M44: 右一字 | N44: 左足後千鳥・右手打上受し、打落受の段受・右足順蹴、蜘蛛足退 | O44: 188 | P44: 少林寺拳法教範(下巻抜粋)_188-189.pdf
A45: 44 | B45: 3 | C45: =VLOOKUP($B45,拳系マスタ!$A:$B,2,FALSE) -> 天王拳 | D45: 突天三 | E45: つきてんさん | F45: 6 | G45: =VLOOKUP($F45,階級マスタ!$A:$B,2,FALSE) -> ① | H45: 1 | I45: =VLOOKUP($H45,分類マスタ!$A:$B,2,FALSE) -> 剛法 | J45: 開 | K45: 左中段 | L45: 左拳上段・右拳中段・左拳上段 | M45: 右一字 | N45: 左足後千鳥・右手上受・（左手下受+右手内受）・右手上受・右足蹴上 | O45: 189 | P45: 少林寺拳法教範(下巻抜粋)_188-189.pdf
...

Sheet 特昇対策
A1: =COUNTIF(A2:A11,TRUE) -> 0 | C1: 仁王拳 | E1: 構/守/攻 | F1: 攻撃 | G1: 教範 | H1: はじめよう！ | I1: ー愛の価値
A2: FALSE | B2: =ROW()-1 -> 1 | C2: 開身突(表) | D2: 二 | E2: 開/乱/中 | F2: 上逆 | G2: 176 | I2: 104 | M2: 両手送小手 | N2: =VLOOKUP(M2,C:C,1,FALSE) -> 両手送小手
A3: FALSE | B3: =ROW()-1 -> 2 | C3: 開身突(裏) | D3: 二 | E3: 対/乱/中 | F3: 上逆 | G3: 176 | M3: 送小手送指捕 | N3: =VLOOKUP(M3,C:C,1,FALSE) -> #N/A
A4: FALSE | B4: =ROW()-1 -> 3 | C4: 半月蹴 | D4: 二 | E4: 対/乱/中 | F4: 上逆 | G4: 177 | I4: 107 | M4: 送横天秤 | N4: =VLOOKUP(M4,C:C,1,FALSE) -> 送横天秤
A5: FALSE | B5: =ROW()-1 -> 4 | C5: 待ち蹴 | D5: 三 | E5: 開/一/中 | F5: 上逆 | G5: 177 | M5: 送巻天秤 | N5: =VLOOKUP(M5,C:C,1,FALSE) -> 送巻天秤
A6: FALSE | B6: =ROW()-1 -> 5 | C6: 下受突 | D6: 三 | E6: 対/八/中 | F6: 中逆 | G6: 177 | H6: 58 | I6: 105 | M6: 送四指捕 | N6: =VLOOKUP(M6,C:C,1,FALSE) -> 送四指捕
A7: FALSE | B7: =ROW()-1 -> 6 | C7: 下受段突 | D7: 三 | E7: 対/八/中 | F7: 中逆 | G7: 177 | I7: 106 | M7: 合掌送捕 | N7: =VLOOKUP(M7,C:C,1,FALSE) -> 合掌送捕
A8: FALSE | B8: =ROW()-1 -> 7 | C8: 外受段突 | D8: 三 | E8: 対/一/中 | F8: 上逆 | G8: 178 | I8: 99 | M8: 送肘攻 | N8: =VLOOKUP(M8,C:C,1,FALSE) -> 送肘攻
A9: FALSE | B9: =ROW()-1 -> 8 | C9: 打上段突 | D9: 三 | E9: 対/一/中 | F9: 上逆 | G9: 178 | M9: 吊落 | N9: =VLOOKUP(M9,C:C,1,FALSE) -> 吊落
A10: FALSE | B10: =ROW()-1 -> 9 | C10: 短刀突込み下受打落蹴 | D10: 三 | E10: 対/八/中 | F10: 突込 | G10: 179 | M10: 吊上捕 | N10: =VLOOKUP(M10,C:C,1,FALSE) -> 吊上捕
A11: FALSE | B11: =ROW()-1 -> 10 | C11: 短刀振上げ流水蹴 | D11: 三 | E11: 開/一/中 | F11: 振上 | M11: 送捕 | N11: =VLOOKUP(M11,C:C,1,FALSE) -> 送捕
M12: 送天秤捕（二種） | N12: =VLOOKUP(M12,C:C,1,FALSE) -> #N/A
A13: =COUNTIF(A14:A22,TRUE) -> 0 | C13: 三合拳 | E13: 構/守/攻 | F13: 攻撃 | G13: 教範 | H13: はじめよう！ | I13: ー愛の価値 | M13: 片手寄抜 | N13: =VLOOKUP(M13,C:C,1,FALSE) -> 片手寄抜
A14: FALSE | B14: =ROW()-13 -> 1 | C14: 払受蹴 | D14: ① | E14: 開/一/一 | F14: 込廻 | G14: 180 | M14: 両手寄抜 | N14: =VLOOKUP(M14,C:C,1,FALSE) -> 両手寄抜
A15: FALSE | B15: =ROW()-13 -> 2 | C15: 下段返 | D15: 初 | E15: 開/一/一 | F15: 込廻 | G15: 180 | I15: 116 | M15: 巻抜(両手) | N15: =VLOOKUP(M15,C:C,1,FALSE) -> 巻抜(両手)
A16: FALSE | B16: =ROW()-13 -> 3 | C16: 中段返 | D16: 三 | E16: 開/待/一 | F16: 込廻 | G16: 180 | I16: 118 | M16: 巻抜(片手) | N16: =VLOOKUP(M16,C:C,1,FALSE) -> 巻抜(片手)
A17: FALSE | B17: =ROW()-13 -> 4 | C17: 下受蹴 | D17: ⑤ | E17: 対/八/中 | F17: 中逆 | G17: 182 | H17: 60 | I17: 109 | M17: 諸手巻抜 | N17: =VLOOKUP(M17,C:C,1,FALSE) -> 諸手巻抜
A18: FALSE | B18: =ROW()-13 -> 5 | C18: 下受順蹴 | D18: ⑤ | E18: 対/八/中 | F18: 中順 | G18: 182 | H18: 62 | I18: 110 | M18: 肘抜より前天秤 | N18: =VLOOKUP(M18,C:C,1,FALSE) -> 肘抜より前天秤
A19: FALSE | B19: =ROW()-13 -> 6 | C19: 逆転身蹴 | D19: 初 | E19: 開/八/一 | F19: 替中 | G19: 183 | H19: 72 | M19: 突抜(両手) | N19: =VLOOKUP(M19,C:C,1,FALSE) -> 突抜(両手)
A20: FALSE | B20: =ROW()-13 -> 7 | C20: 半転身蹴 | D20: ② | E20: 開/中/一 | F20: 中逆 | G20: 183 | I20: 114 | M20: 突抜(外) | N20: =VLOOKUP(M20,C:C,1,FALSE) -> 突抜(外)
A21: FALSE | B21: =ROW()-13 -> 8 | C21: 横転身蹴 | D21: ② | E21: 対/中/一 | F21: 中逆 | G21: 183 | H21: 70 | I21: 112 | M21: 突抜(内) | N21: =VLOOKUP(M21,C:C,1,FALSE) -> 突抜(内)
A22: FALSE | B22: =ROW()-13 -> 9 | C22: 十字受蹴 | D22: ③ | E22: 対/一/一 | F22: 込廻 | G22: 183 | H22: 74 | I22: 108 | M22: 諸手突抜 | N22: =VLOOKUP(M22,C:C,1,FALSE) -> 諸手突抜
M23: 打抜(片手) | N23: =VLOOKUP(M23,C:C,1,FALSE) -> 打抜(片手)
A24: =COUNTIF(A25:A33,TRUE) -> 0 | C24: 天王拳 | E24: 構/守/攻 | F24: 攻撃 | G24: 教範 | H24: はじめよう！ | I24: ー愛の価値 | M24: 打抜(両手) | N24: =VLOOKUP(M24,C:C,1,FALSE) -> 打抜(両手)
A25: FALSE | B25: =ROW()-24 -> 1 | C25: 突天一 | D25: ③ | E25: 開/一/中 | F25: 上順突・中逆突 | G25: 185 | H25: 64 | I25: 120 | M25: 押小手(片手) | N25: =VLOOKUP(M25,C:C,1,FALSE) -> 押小手(片手)
A26: FALSE | B26: =ROW()-24 -> 2 | C26: 蹴天一 | D26: 三 | E26: 開/一/中 | F26: 上逆 | G26: 186 | M26: 押小手(両手) | N26: =VLOOKUP(M26,C:C,1,FALSE) -> 押小手(両手)
A27: FALSE | B27: =ROW()-24 -> 3 | C27: 逆天一 | D27: 二 | E27: 開/一/中 | F27: 上逆 | G27: 187 | I27: 127 | M27: 抜打押小手 | N27: =VLOOKUP(M27,C:C,1,FALSE) -> 抜打押小手
A28: FALSE | B28: =ROW()-24 -> 4 | C28: 振天二 | D28: ① | E28: 開/一/一 | F28: 横振・上振 | G28: 188 | M28: 小手巻返 | N28: =VLOOKUP(M28,C:C,1,FALSE) -> 小手巻返
A29: FALSE | B29: =ROW()-24 -> 5 | C29: 突天二 | D29: ① | E29: 開/中/中 | F29: 上順突・中逆突 | G29: 188 | M29: 二段抜 | N29: =VLOOKUP(M29,C:C,1,FALSE) -> 二段抜
A30: FALSE | B30: =ROW()-24 -> 6 | C30: 蹴天三 | D30: ① | E30: 開/一/中 | F30: 上順突・中逆突・中逆蹴 | G30: 189 | I30: 122 | M30: 片手押抜 | N30: =VLOOKUP(M30,C:C,1,FALSE) -> 片手押抜
A31: FALSE | B31: =ROW()-24 -> 7 | C31: 突天三 | D31: ① | E31: 開/一/中 | F31: 上順突・中逆突・上順突 | G31: 189 | I31: 124 | M31: 諸手押抜 | N31: =VLOOKUP(M31,C:C,1,FALSE) -> 諸手押抜
A32: FALSE | B32: =ROW()-24 -> 8 | C32: 混天一 | D32: ② | E32: 開/一/一 | F32: 上横振・中逆突 | G32: 190 | M32: 巻小手(片手) | N32: =VLOOKUP(M32,C:C,1,FALSE) -> 巻小手(片手)
A33: FALSE | B33: =ROW()-24 -> 9 | C33: 対天一 | D33: 二 | E33: 対/一/中 | F33: 上順 | G33: 191 | I33: 126 | M33: 巻小手(諸手) | N33: =VLOOKUP(M33,C:C,1,FALSE) -> 巻小手(諸手)
M34: 切抜(外) | N34: =VLOOKUP(M34,C:C,1,FALSE) -> 切抜(外)
A35: =COUNTIF(A36:A41,TRUE) -> 0 | C35: 白蓮拳 | E35: 構/守/攻 | F35: 攻撃 | G35: 教範 | H35: はじめよう！ | I35: ー愛の価値 | M35: 切抜(内) | N35: =VLOOKUP(M35,C:C,1,FALSE) -> 切抜(内)
A36: FALSE | B36: =ROW()-35 -> 1 | C36: 燕返 | D36: ① | E36: 開/待/中 | F36: 上直突 | G36: 193 | H36: 76 | I36: 130 | M36: 合掌抜 | N36: =VLOOKUP(M36,C:C,1,FALSE) -> 合掌抜
A37: FALSE | B37: =ROW()-35 -> 2 | C37: 千鳥返 | D37: ① | E37: 対/待/中 | F37: 替上順突 | G37: 193 | H37: 78 | I37: 128 | M37: 諸手引抜 | N37: =VLOOKUP(M37,C:C,1,FALSE) -> 諸手引抜
A38: FALSE | B38: =ROW()-35 -> 3 | C38: 半月返・掬首投 | D38: 三 | E38: 対/乱/中 | F38: 上中 | G38: 194 | I38: 131 | M38: 切小手(片手) | N38: =VLOOKUP(M38,C:C,1,FALSE) -> 切小手(片手)
A39: FALSE | B39: =ROW()-35 -> 4 | C39: 払受段突 | D39: 二 | E39: 開/一/一 | F39: 込廻 | G39: 194 | I39: 132 | M39: 切返小手 | N39: =VLOOKUP(M39,C:C,1,FALSE) -> 切返小手
A40: FALSE | B40: =ROW()-35 -> 5 | C40: 水月返 | D40: 三 | E40: 対/待/中 | F40: 上逆 | G40: 194 | I40: 136 | M40: 切返投 | N40: =VLOOKUP(M40,C:C,1,FALSE) -> 切返投
...

Sheet 剛法
A1: 法形 | C1: 構え | D1: 攻者 | F1: 守者 | H1: 付記
A2: 仁王拳 | C2: 上段攻防を主体とする法形（左右表裏、四法ある場合が殆どです。）
A3: 流水蹴（後） | B3: ⑥ | C3: ／開＼ | D3: ・左中段 | E3: 上段逆突 | F3: 右一字・ | G3: 後流水・右手で高めの流水受け・順蹴 | H3: 守者：肩を顎の前まで
A4: 流水蹴（前） | B4: ⑤ | C4: /対/ | D4: ・左中段 | E4: 上段逆突 | F4: ・左一字 | G4: 前流水・右手で高めの流水受け・逆蹴 | H4: 守者：肩をまわす
A5: 転身蹴 | B5: ⑥ | C5: /対/ | D5: ・左中段 | E5: 上段逆突 | F5: ・左一字 | G5: やや後屈、左転身・右足逆蹴・順下りか蜘蛛足下り | H5: 守者：肩をまわさない・流水受けなし
A6: 内受突（裏） | B6: ⑥ | C6: /対/ | D6: ・左中段 | E6: 上段逆突 | F6: ・左一字 | G6: 左前千鳥・左手内受（そのまま頭を守る）・中段逆突・右足蹴込 | H6: 守者：手首を高く払う、攻撃深く
A7: 内受突（表） | B7: ② | C7: ／開＼ | D7: ・左中段 | E7: 上段逆突 | F7: 右一字・ | G7: 右前千鳥・右手内受（そのまま頭を守る）・中段逆突 | H7: 守者：前の手の外腕刀で内受け
A8: 内受蹴（表） | B8: ③ | C8: ／開＼ | D8: ・左中段 | E8: 上段逆突 | F8: 右一字・ | G8: 内受（肩を回しながら前足を後足に寄せる）・順蹴足刀・踏込、右手刀 | H8: 守者：肩を十分回し足刀体勢へ
A9: 内受蹴（裏） | B9: ③ | C9: /対/ | D9: ・左中段 | E9: 上段逆突 | F9: ・左一字 | G9: 内受（肩を回しながら前足を後足に寄せる）・順蹴足刀・踏込、右手刀 | H9: 守者：肩を十分回し足刀体勢へ
A10: 上受突（表） | B10: ⑥ | C10: /対/ | D10: ・左中段 | E10: 逆手刀 | F10: ・左一字 | G10: やや前屈、右転身・左手上受・右拳中段・左手熊手・右手で手払 | H10: 守者：転身時、右足先は相手の方向に
A11: 上受突（裏） | B11: ⑥ | C11: /対/ | D11: ・左中段 | E11: 逆手刀 | F11: ・左一字 | G11: やや前屈、左転身・右手上受・左拳中段・左手で手払 | H11: 守者：左に回り込む感じ
A12: 上受蹴（表） | B12: ⑤ | C12: /対/ | D12: ・左中段 | E12: 逆手刀 | F12: ・左一字 | G12: やや右足下がり左手上受・順蹴 | H12: 守者：攻者手首を切り上げるつもり
A13: 上受蹴（裏） | B13: ⑤ | C13: /対/ | D13: ・左中段 | E13: 逆手刀 | F13: ・左一字 | G13: 左転身・右手上受・右足逆蹴 | H13: 守者：攻者手首を切り上げるつもり
A14: 外受蹴 | B14: ④ | C14: /対/ | D14: ・左中段 | E14: 上段逆突 | F14: ・左一字 | G14: 左転身・逆足で蹴上（もしくは回し蹴） | H14: 守者：外受突きより左に大きく
... A30: 半月蹴 | B30: 二 | C30: /対/ | D30: ・左中段 | E30: 上段逆突 | F30: ・左乱 | G30: 開身・右手半月受・右足逆蹴 | H30: 守者：体を開いて半月受
A31: 下受突 | B31: 三 | C31: /対/ | D31: ・左一字 | E31: 中段逆突 | F31: ・左八双 | G31: 左足左横に出し、左下受・右拳上段突
A32: 下受段突 | B32: 三 | C32: /対/ | D32: ・左一字 | E32: 中段逆突 | F32: ・左八双 | G32: 左足左横に出し、左下受し、直ちに左拳上段裏拳突 | H32: 守者：受けた後、上体の重心を前移動させながら裏拳打込
A33: 短刀突込下受打落蹴 | B33: 三 | C33: /対/ | D33: ・左一字 | E33: 短刀で中段逆突 | F33: ・左八双 | G33: 下受蹴の要領で、左下受・もう一方の手で短刀打落・右足逆蹴 | H33: 守者：体捌きがなければ危険
A34: 短刀振上流水蹴 | B34: 三 | C34: ／開＼ | D34: ・左中段 | E34: 右手で短刀振り下ろし | F34: 右一字・ | G34: 後流水蹴の要領で、流水受け・順蹴・十字足退 | H34: 守者：体捌きがなければ危険
A35: 三合拳 | C35: 中段攻防を主体とし、手で受け足で反撃する法形
A36: 下受蹴 | B36: ⑤ | C36: /対/ | D36: ・左一字 | E36: 右手中段逆突 | F36: ・左八双 | G36: 左に転身・左手下受・右足逆蹴中段 | H36: 攻者：一字構え 守者：開気味に転身
A37: 下受順蹴 | B37: ⑤ | C37: /対/ | D37: ・左一字 | E37: 左手中段順突 | F37: ・左八双 | G37: やや前屈、開気味に構える 右に転身・右下受・左足順蹴 | H37: 攻者：開き構えから差し替え順突の場合もあり
A38: 十字受蹴 | B38: ③ | C38: /対/ | D38: 右一字・ | E38: 差込右足中段回蹴 | F38: 右一字・ | G38: やや前屈・横十字受・前足引き足、そのまま蹴り返し | H38: 攻者：差込回蹴 守者：金的を守るように引き足
A39: 横転身蹴 | B39: ② | C39: /対/ | D39: ・左一字 | E39: 左足差込、右足中段逆蹴 | F39: ・左中段 | G39: やや前屈、右に開気味に転身・左圧拳打払受・右外受・中段順蹴 | H39: 攻者：差込逆蹴
A40: 半転身蹴 | B40: ② | C40: ／開＼ | D40: 右一字・ | E40: 右足差込、左足中段逆蹴 | F40: ・左中段 | G40: 右半転身・左拳圧拳打落（引込むごとく）・右拳外受・左順蹴 | H40: 攻者：差込逆蹴 守者：半転身を十分に（足捌き）
A41: 逆転身蹴 | B41: 初 | C41: ／開＼ | D41: ・左一字 | E41: 差替中段順突 | F41: 右八双・ | G41: 右足逆転身・左下受・左足廻蹴
A42: 払受蹴 | B42: ① | C42: ／開＼ | D42: ・左一字 | E42: 左差込廻蹴 | F42: 右一字・ | G42: 右三枚誘い・右足を左足の前に右丁字に踏み入れ・右手払受・左直蹴 | H42: 守者：蹴りは上部に受け流す
A43: 下段返 | B43: 初 | C43: ／開＼ | D43: ・左一字 | E43: 左差込廻蹴 | F43: 右一字・ | G43: 右三枚誘い・左足左横に出し、右手払受・右足直蹴 | H43: 守者：蹴りと受けは同時に
A44: 中段返 | B44: 初 | C44: ／開＼ | D44: ・左一字 | E44: 左差込廻蹴 | F44: ・左待機 | G44: 左足を右足前に引きつつ体捻しながら右手下受・右足直蹴 | H44: 守者：やや半身（中段攻撃を誘う） 下受と同時に、上段を警戒し左拳外受
A45: 天王拳 | C45: 上段より始まる連攻防の基本形（左右表裏、四法）
A46: 突天一 | B46: ③ | C46: ／開＼ | D46: ・左中段 | E46: 左拳上段・右拳中段 | F46: 右一字・ | G46: 左足後千鳥・右手上受、左手下受の連受・右足順蹴、蜘蛛足退 | H46: 守者：やや開き気味・対の先を取る
A47: 突天二 | B47: ① | C47: ／開＼ | D47: ・左中段 | E47: 左拳上段・右拳上段 | F47: 右一字・ | G47: 左足後千鳥・右手打上受し、打落受の段受・右足順蹴、蜘蛛足退 | H47: 守者：打上握拳、打落開手
A48: 突天三 | B48: ① | C48: ／開＼ | D48: ・左中段 | E48: 左拳上段・右拳中段・左拳上段 | F48: 右一字・ | G48: 左足後千鳥・右手上受・（左手下受+右手内受）・右手上受・右足蹴上
A49: 混天一 | B49: ② | C49: ／開＼ | D49: ・左一字 | E49: 左拳上段振突・右拳中段逆突 | F49: 右一字・ | G49: 左足後千鳥・右手外押受・左下受の連受・右足順蹴・蜘蛛足退
A50: 振天二 | B50: ① | C50: ／開＼ | D50: ・左一字 | E50: 左拳上段振突・右拳上振 | F50: 右一字・ | G50: 順手で外押受+打落受しながら体を十分閉じ、順足刀 | H50: 攻者：アッパーは体に腕を固定し、腰の回転で打つ
A51: 蹴天一 | B51: 三 | C51: /対/ | D51: ・左中段 | E51: 右拳上段・右足廻蹴 | F51: ・左一字 | G51: 右手外受・左手打払受け乍ら掬止め変化・右足で金的蹴・掬投 | H51: 守者：左足を外に出しながら外受
A52: 蹴天三 | B52: ① | C52: ／開＼ | D52: ・左中段 | E52: 左拳上段・右拳中段・右足蹴上 | F52: 右一字・ | G52: 左足後千鳥・右手上受・（左手下受+右手内受）・両手下十字受・右足蹴上 | H52: 攻者：直蹴りも可 守者：やや左に転身
A53: 対天一 | B53: 二 | C53: /対/ | D53: ・左中段 | E53: 左拳上段・右拳中段 | F53: ・左一字 | G53: 右足後千鳥・右手上受・左手下受・左足廻蹴・蜘蛛足退 | H53: 突天一の対構えバージョン
A54: 逆天一 | B54: 二 | C54: ／開＼ | D54: ・左中段 | E54: 右拳上段逆突・左拳中段順突 | F54: 右一字・ | G54: 左足後千鳥・左手内受・右手払受・右足順蹴・蜘蛛足退 | H54: 守者：千鳥退の時、遠間になりすぎぬよう
A55: 白蓮拳 | C55: 受け手が直ちに攻撃に用いられる二段用法を主体とする段攻防の基本形
...

Sheet 柔法
A1: 柔法系統別一覧 | E1: =COUNTIF(E3:E52,">0") -> 46 | J1: =COUNTIF(J3:J52,">0") -> 41 | O1: =COUNTIF(O3:O52,">0") -> 23
A2: 系統別 | B2: 技 | C2: 段位 | D2: 拳系 | F2: 系統別 | G2: 技 | H2: 段位 | I2: 拳系 | K2: 系統別 | L2: 技 | M2: 段位 | N2: 拳系 | P2: 系統別 | Q2: 技 | R2: 段位 | S2: 拳系
A3: 送小手系 | B3: 両手送小手 | C3: 2 | D3: 龍華拳 | E3: =LEN(_xlfn.IFNA(VLOOKUP(B3,特昇対策!$C:$C,1,FALSE),IF(OR(D3="龍王拳",D3="龍華拳",C3="二",C3="三",C3="四"),B3,""))) -> 5 | F3: 片胸落系 | G3: 襟十字 | H3: 1 | I3: 羅漢拳 | J3: =LEN(_xlfn.IFNA(VLOOKUP(G3,特昇対策!$C:$C,1,FALSE),IF(OR(I3="龍王拳",I3="龍華拳",H3="二",H3="三",H3="四"),G3,""))) -> 0 | K3: 天秤投 | L3: 引天秤 | M3: 二 | N3: 五花拳 | O3: =LEN(_xlfn.IFNA(VLOOKUP(L3,特昇対策!$C:$C,1,FALSE),IF(OR(N3="龍王拳",N3="龍華拳",M3="二",M3="三",M3="四"),L3,""))) -> 3 | P3: 金剛拳 | Q3: 腕十字 | R3: 初
B4: 送小手送指捕 | C4: 2 | D4: 金剛拳 | E4: =LEN(_xlfn.IFNA(VLOOKUP(B4,特昇対策!$C:$C,1,FALSE),IF(OR(D4="龍王拳",D4="龍華拳",C4="二",C4="三",C4="四"),B4,""))) -> 0 | G4: 片胸落 | H4: 1 | I4: 羅漢拳 | J4: =LEN(_xlfn.IFNA(VLOOKUP(G4,特昇対策!$C:$C,1,FALSE),IF(OR(I4="龍王拳",I4="龍華拳",H4="二",H4="三",H4="四"),G4,""))) -> 0 | L4: 逆引天秤 | M4: 二 | N4: 五花拳 | O4: =LEN(_xlfn.IFNA(VLOOKUP(L4,特昇対策!$C:$C,1,FALSE),IF(OR(N4="龍王拳",N4="龍華拳",M4="二",M4="三",M4="四"),L4,""))) -> 4 | Q4: 前指固 | R4: 初
B5: 送横天秤 | C5: 2 | D5: 龍華拳 | E5: =LEN(_xlfn.IFNA(VLOOKUP(B5,特昇対策!$C:$C,1,FALSE),IF(OR(D5="龍王拳",D5="龍華拳",C5="二",C5="三",C5="四"),B5,""))) -> 4 | G5: 引胸落 | H5: 二 | I5: 羅漢拳 | J5: =LEN(_xlfn.IFNA(VLOOKUP(G5,特昇対策!$C:$C,1,FALSE),IF(OR(I5="龍王拳",I5="龍華拳",H5="二",H5="三",H5="四"),G5,""))) -> 3 | L5: 合掌引天秤 | M5: 三 | N5: 五花拳 | O5: =LEN(_xlfn.IFNA(VLOOKUP(L5,特昇対策!$C:$C,1,FALSE),IF(OR(N5="龍王拳",N5="龍華拳",M5="二",M5="三",M5="四"),L5,""))) -> 5 | Q5: 送固 | R5: 初
B6: 送巻天秤 | C6: 4 | D6: 龍華拳 | E6: =LEN(_xlfn.IFNA(VLOOKUP(B6,特昇対策!$C:$C,1,FALSE),IF(OR(D6="龍王拳",D6="龍華拳",C6="二",C6="三",C6="四"),B6,""))) -> 4 | G6: 両胸落 | H6: 二 | I6: 羅漢拳 | J6: =LEN(_xlfn.IFNA(VLOOKUP(G6,特昇対策!$C:$C,1,FALSE),IF(OR(I6="龍王拳",I6="龍華拳",H6="二",H6="三",H6="四"),G6,""))) -> 3 | L6: 天秤投 | M6: 四 | N6: 五花拳 | O6: =LEN(_xlfn.IFNA(VLOOKUP(L6,特昇対策!$C:$C,1,FALSE),IF(OR(N6="龍王拳",N6="龍華拳",M6="二",M6="三",M6="四"),L6,""))) -> 3 | Q6: 裏固 | R6: 初
B7: 送四指捕 | C7: 三 | D7: 龍華拳 | E7: =LEN(_xlfn.IFNA(VLOOKUP(B7,特昇対策!$C:$C,1,FALSE),IF(OR(D7="龍王拳",D7="龍華拳",C7="二",C7="三",C7="四"),B7,""))) -> 4 | F7: 襟系 | G7: 腕巻 | H7: 1 | I7: 羅漢拳 | J7: =LEN(_xlfn.IFNA(VLOOKUP(G7,特昇対策!$C:$C,1,FALSE),IF(OR(I7="龍王拳",I7="龍華拳",H7="二",H7="三",H7="四"),G7,""))) -> 0 | K7: 首投 | L7: 掬首投 | M7: 三 | N7: 羅漢拳 | O7: =LEN(_xlfn.IFNA(VLOOKUP(L7,特昇対策!$C:$C,1,FALSE),IF(OR(N7="龍王拳",N7="龍華拳",M7="二",M7="三",M7="四"),L7,""))) -> 3 | Q7: 十字固 | R7: 初
B8: 合掌送捕 | C8: 三 | D8: 金剛拳 | E8: =LEN(_xlfn.IFNA(VLOOKUP(B8,特昇対策!$C:$C,1,FALSE),IF(OR(D8="龍王拳",D8="龍華拳",C8="二",C8="三",C8="四"),B8,""))) -> 4 | G8: 襟捕 | H8: 初 | I8: ？ | J8: =LEN(_xlfn.IFNA(VLOOKUP(G8,特昇対策!$C:$C,1,FALSE),IF(OR(I8="龍王拳",I8="龍華拳",H8="二",H8="三",H8="四"),G8,""))) -> 0 | L8: 半月首投 | M8: 四 | N8: 羅漢拳 | O8: =LEN(_xlfn.IFNA(VLOOKUP(L8,特昇対策!$C:$C,1,FALSE),IF(OR(N8="龍王拳",N8="龍華拳",M8="二",M8="三",M8="四"),L8,""))) -> 4 | Q8: 立合掌固 | R8: 初
B9: 送肘攻 | C9: 二 | D9: 龍華拳 | E9: =LEN(_xlfn.IFNA(VLOOKUP(B9,特昇対策!$C:$C,1,FALSE),IF(OR(D9="龍王拳",D9="龍華拳",C9="二",C9="三",C9="四"),B9,""))) -> 3 | G9: 送襟捕 | H9: 四 | I9: 羅漢拳 | J9: =LEN(_xlfn.IFNA(VLOOKUP(G9,特昇対策!$C:$C,1,FALSE),IF(OR(I9="龍王拳",I9="龍華拳",H9="二",H9="三",H9="四"),G9,""))) -> 3 | L9: 巻打首投 | M9: 四 | N9: 羅漢拳 | O9: =LEN(_xlfn.IFNA(VLOOKUP(L9,特昇対策!$C:$C,1,FALSE),IF(OR(N9="龍王拳",N9="龍華拳",M9="二",M9="三",M9="四"),L9,""))) -> 4 | Q9: 送指捕 | R9: 初
B10: 吊落 | C10: 二 | D10: 龍華拳 | E10: =LEN(_xlfn.IFNA(VLOOKUP(B10,特昇対策!$C:$C,1,FALSE),IF(OR(D10="龍王拳",D10="龍華拳",C10="二",C10="三",C10="四"),B10,""))) -> 2 | G10: 後襟捕（表・裏） | H10: 四 | I10: 羅漢拳 | J10: =LEN(_xlfn.IFNA(VLOOKUP(G10,特昇対策!$C:$C,1,FALSE),IF(OR(I10="龍王拳",I10="龍華拳",H10="二",H10="三",H10="四"),G10,""))) -> 8 | L10: 後首投 | M10: 四 | N10: 羅漢拳 | O10: =LEN(_xlfn.IFNA(VLOOKUP(L10,特昇対策!$C:$C,1,FALSE),IF(OR(N10="龍王拳",N10="龍華拳",M10="二",M10="三",M10="四"),L10,""))) -> 3 | Q10: 前天秤固 | R10: 初
B11: 吊上捕 | C11: 二 | D11: 金剛拳 | E11: =LEN(_xlfn.IFNA(VLOOKUP(B11,特昇対策!$C:$C,1,FALSE),IF(OR(D11="龍王拳",D11="龍華拳",C11="二",C11="三",C11="四"),B11,""))) -> 3 | G11: 襟抜 | H11: 1 | I11: 龍王拳 | J11: =LEN(_xlfn.IFNA(VLOOKUP(G11,特昇対策!$C:$C,1,FALSE),IF(OR(I11="龍王拳",I11="龍華拳",H11="二",H11="三",H11="四"),G11,""))) -> 2 | K11: 木葉系 | L11: 木葉送 | M11: 三 | N11: 龍華拳 | O11: =LEN(_xlfn.IFNA(VLOOKUP(L11,特昇対策!$C:$C,1,FALSE),IF(OR(N11="龍王拳",N11="龍華拳",M11="二",M11="三",M11="四"),L11,""))) -> 3 | Q11: 天秤固（裏） | R11: 初
B12: 送捕 | C12: 2 | D12: 龍華拳 | E12: =LEN(_xlfn.IFNA(VLOOKUP(B12,特昇対策!$C:$C,1,FALSE),IF(OR(D12="龍王拳",D12="龍華拳",C12="二",C12="三",C12="四"),B12,""))) -> 2 | F12: 袖系 | G12: 上膊捕 | H12: 2 | I12: 羅漢拳 | J12: =LEN(_xlfn.IFNA(VLOOKUP(G12,特昇対策!$C:$C,1,FALSE),IF(OR(I12="龍王拳",I12="龍華拳",H12="二",H12="三",H12="四"),G12,""))) -> 0 | L12: 木葉返 | M12: 三 | N12: 龍華拳 | O12: =LEN(_xlfn.IFNA(VLOOKUP(L12,特昇対策!$C:$C,1,FALSE),IF(OR(N12="龍王拳",N12="龍華拳",M12="二",M12="三",M12="四"),L12,""))) -> 3 | Q12: 閂固 | R12: 初
B13: 送天秤捕（二種） | C13: 二 | D13: 金剛拳 | E13: =LEN(_xlfn.IFNA(VLOOKUP(B13,特昇対策!$C:$C,1,FALSE),IF(OR(D13="龍王拳",D13="龍華拳",C13="二",C13="三",C13="四"),B13,""))) -> 8 | G13: 引落 | H13: 1 | I13: 羅漢拳 | J13: =LEN(_xlfn.IFNA(VLOOKUP(G13,特昇対策!$C:$C,1,FALSE),IF(OR(I13="龍王拳",I13="龍華拳",H13="二",H13="三",H13="四"),G13,""))) -> 0 | L13: 送指返 | M13: 三 | N13: 龍華拳 | O13: =LEN(_xlfn.IFNA(VLOOKUP(L13,特昇対策!$C:$C,1,FALSE),IF(OR(N13="龍王拳",N13="龍華拳",M13="二",M13="三",M13="四"),L13,""))) -> 3 | Q13: 送天秤捕（二種） | R13: 二
B14: 寄抜（片・両） | C14: 5・3 | D14: 龍王拳 | E14: =LEN(_xlfn.IFNA(VLOOKUP(B14,特昇対策!$C:$C,1,FALSE),IF(OR(D14="龍王拳",D14="龍華拳",C14="二",C14="三",C14="四"),B14,""))) -> 7 | G14: 袖捕 | H14: 1 | I14: 羅漢拳 | J14: =LEN(_xlfn.IFNA(VLOOKUP(G14,特昇対策!$C:$C,1,FALSE),IF(OR(I14="龍王拳",I14="龍華拳",H14="二",H14="三",H14="四"),G14,""))) -> 0 | K14: 閂系 | L14: 閂送（捕） | M14: 四 | N14: 金剛拳 | O14: =LEN(_xlfn.IFNA(VLOOKUP(L14,特昇対策!$C:$C,1,FALSE),IF(OR(N14="龍王拳",N14="龍華拳",M14="二",M14="三",M14="四"),L14,""))) -> 5 | Q14: 立一字固 | R14: 二
B15: 巻抜（片・両・諸） | C15: 5・3・初 | D15: 龍王拳 | E15: =LEN(_xlfn.IFNA(VLOOKUP(B15,特昇対策!$C:$C,1,FALSE),IF(OR(D15="龍王拳",D15="龍華拳",C15="二",C15="三",C15="四"),B15,""))) -> 9 | G15: 袖巻 | H15: 1 | I15: 羅漢拳 | J15: =LEN(_xlfn.IFNA(VLOOKUP(G15,特昇対策!$C:$C,1,FALSE),IF(OR(I15="龍王拳",I15="龍華拳",H15="二",H15="三",H15="四"),G15,""))) -> 0 | L15: 閂外天秤 | M15: 四 | N15: 五花拳 | O15: =LEN(_xlfn.IFNA(VLOOKUP(L15,特昇対策!$C:$C,1,FALSE),IF(OR(N15="龍王拳",N15="龍華拳",M15="二",M15="三",M15="四"),L15,""))) -> 4 | Q15: 背越一字固 | R15: 二
B16: 肘抜前天秤 | C16: 初 | D16: 龍王拳 | E16: =LEN(_xlfn.IFNA(VLOOKUP(B16,特昇対策!$C:$C,1,FALSE),IF(OR(D16="龍王拳",D16="龍華拳",C16="二",C16="三",C16="四"),B16,""))) -> 5 | G16: 袖巻天秤 | H16: 1 | I16: 羅漢拳 | J16: =LEN(_xlfn.IFNA(VLOOKUP(G16,特昇対策!$C:$C,1,FALSE),IF(OR(I16="龍王拳",I16="龍華拳",H16="二",H16="三",H16="四"),G16,""))) -> 0 | K16: 居捕 | L16: 上抜 | M16: 三 | N16: 龍王拳 | O16: =LEN(_xlfn.IFNA(VLOOKUP(L16,特昇対策!$C:$C,1,FALSE),IF(OR(N16="龍王拳",N16="龍華拳",M16="二",M16="三",M16="四"),L16,""))) -> 2 | Q16: 吊上捕 | R16: 二
B17: 突抜（（内・外）・両・諸） | C17: 4・3・1 | D17: 龍王拳 | E17: =LEN(_xlfn.IFNA(VLOOKUP(B17,特昇対策!$C:$C,1,FALSE),IF(OR(D17="龍王拳",D17="龍華拳",C17="二",C17="三",C17="四"),B17,""))) -> 13 | G17: 後袖巻（捕） | H17: 四 | I17: 羅漢拳 | J17: =LEN(_xlfn.IFNA(VLOOKUP(G17,特昇対策!$C:$C,1,FALSE),IF(OR(I17="龍王拳",I17="龍華拳",H17="二",H17="三",H17="四"),G17,""))) -> 6 | L17: 居捕送小手 | M17: 三 | N17: 龍華拳 | O17: =LEN(_xlfn.IFNA(VLOOKUP(L17,特昇対策!$C:$C,1,FALSE),IF(OR(N17="龍王拳",N17="龍華拳",M17="二",M17="三",M17="四"),L17,""))) -> 5 | Q17: 吊上裏固 | R17: 二
B18: 打抜（片・両） | C18: 二 | D18: 龍王拳 | E18: =LEN(_xlfn.IFNA(VLOOKUP(B18,特昇対策!$C:$C,1,FALSE),IF(OR(D18="龍王拳",D18="龍華拳",C18="二",C18="三",C18="四"),B18,""))) -> 7 | G18: 袖巻返 | H18: 三 | I18: 羅漢拳 | J18: =LEN(_xlfn.IFNA(VLOOKUP(G18,特昇対策!$C:$C,1,FALSE),IF(OR(I18="龍王拳",I18="龍華拳",H18="二",H18="三",H18="四"),G18,""))) -> 3 | L18: 居捕逆小手 | M18: 三 | N18: 龍華拳 | O18: =LEN(_xlfn.IFNA(VLOOKUP(L18,特昇対策!$C:$C,1,FALSE),IF(OR(N18="龍王拳",N18="龍華拳",M18="二",M18="三",M18="四"),L18,""))) -> 5 | Q18: 蜘蛛絡 | R18: 二
A19: 押小手系 | B19: 押小手（片・両） | C19: 初 | D19: 龍華拳 | E19: =LEN(_xlfn.IFNA(VLOOKUP(B19,特昇対策!$C:$C,1,FALSE),IF(OR(D19="龍王拳",D19="龍華拳",C19="二",C19="三",C19="四"),B19,""))) -> 8 | G19: 袖口捕 | H19: 三 | I19: 羅漢拳 | J19: =LEN(_xlfn.IFNA(VLOOKUP(G19,特昇対策!$C:$C,1,FALSE),IF(OR(I19="龍王拳",I19="龍華拳",H19="二",H19="三",H19="四"),G19,""))) -> 3 | L19: 居捕押小手 | M19: 三 | N19: 龍華拳 | O19: =LEN(_xlfn.IFNA(VLOOKUP(L19,特昇対策!$C:$C,1,FALSE),IF(OR(N19="龍王拳",N19="龍華拳",M19="二",M19="三",M19="四"),L19,""))) -> 5 | Q19: 裏合掌固 | R19: 二
B20: 抜打押小手 | C20: 二 | D20: 龍華拳 | E20: =LEN(_xlfn.IFNA(VLOOKUP(B20,特昇対策!$C:$C,1,FALSE),IF(OR(D20="龍王拳",D20="龍華拳",C20="二",C20="三",C20="四"),B20,""))) -> 5 | G20: 袖口巻 | H20: 三 | I20: 羅漢拳 | J20: =LEN(_xlfn.IFNA(VLOOKUP(G20,特昇対策!$C:$C,1,FALSE),IF(OR(I20="龍王拳",I20="龍華拳",H20="二",H20="三",H20="四"),G20,""))) -> 3 | K20: 合掌系 | L20: 送合掌（二種） | M20: 四 | N20: 龍華拳 | O20: =LEN(_xlfn.IFNA(VLOOKUP(L20,特昇対策!$C:$C,1,FALSE),IF(OR(N20="龍王拳",N20="龍華拳",M20="二",M20="三",M20="四"),L20,""))) -> 7 | Q20: 裏膝固 | R20: 二
B21: 小手巻返 | C21: 初 | D21: 龍華拳 | E21: =LEN(_xlfn.IFNA(VLOOKUP(B21,特昇対策!$C:$C,1,FALSE),IF(OR(D21="龍王拳",D21="龍華拳",C21="二",C21="三",C21="四"),B21,""))) -> 4 | G21: 逆袖捕 | H21: 四 | I21: 羅漢拳 | J21: =LEN(_xlfn.IFNA(VLOOKUP(G21,特昇対策!$C:$C,1,FALSE),IF(OR(I21="龍王拳",I21="龍華拳",H21="二",H21="三",H21="四"),G21,""))) -> 3 | L21: 逆合掌投（二種） | M21: 四 | N21: 龍華拳 | O21: =LEN(_xlfn.IFNA(VLOOKUP(L21,特昇対策!$C:$C,1,FALSE),IF(OR(N21="龍王拳",N21="龍華拳",M21="二",M21="三",M21="四"),L21,""))) -> 8 | Q21: 龍固 | R21: 二
B22: 二段抜 | C22: 3 | D22: 龍王拳 | E22: =LEN(_xlfn.IFNA(VLOOKUP(B22,特昇対策!$C:$C,1,FALSE),IF(OR(D22="龍王拳",D22="龍華拳",C22="二",C22="三",C22="四"),B22,""))) -> 3 | G22: 逆袖巻 | H22: 四 | I22: 羅漢拳 | J22: =LEN(_xlfn.IFNA(VLOOKUP(G22,特昇対策!$C:$C,1,FALSE),IF(OR(I22="龍王拳",I22="龍華拳",H22="二",H22="三",H22="四"),G22,""))) -> 3 | L22: 合掌丁字 | M22: 四 | N22: 龍華拳 | O22: =LEN(_xlfn.IFNA(VLOOKUP(L22,特昇対策!$C:$C,1,FALSE),IF(OR(N22="龍王拳",N22="龍華拳",M22="二",M22="三",M22="四"),L22,""))) -> 4 | P22: 攻撃技 | Q22: 腕逆捕
B23: 押抜（片・諸） | C23: 1・初 | D23: 龍王拳 | E23: =LEN(_xlfn.IFNA(VLOOKUP(B23,特昇対策!$C:$C,1,FALSE),IF(OR(D23="龍王拳",D23="龍華拳",C23="二",C23="三",C23="四"),B23,""))) -> 7 | G23: 袖抜 | H23: 1 | I23: 龍王拳 | J23: =LEN(_xlfn.IFNA(VLOOKUP(G23,特昇対策!$C:$C,1,FALSE),IF(OR(I23="龍王拳",I23="龍華拳",H23="二",H23="三",H23="四"),G23,""))) -> 2 | L23: 合掌突倒 | M23: 四 | N23: 龍華拳 | O23: =LEN(_xlfn.IFNA(VLOOKUP(L23,特昇対策!$C:$C,1,FALSE),IF(OR(N23="龍王拳",N23="龍華拳",M23="二",M23="三",M23="四"),L23,""))) -> 4 | Q23: 逆天秤
A24: 巻小手系 | B24: 巻小手（片・諸） | C24: 1 | D24: 龍華拳 | E24: =LEN(_xlfn.IFNA(VLOOKUP(B24,特昇対策!$C:$C,1,FALSE),IF(OR(D24="龍王拳",D24="龍華拳",C24="二",C24="三",C24="四"),B24,""))) -> 8 | G24: 上膊抜（片・両） | H24: 2 | I24: 龍王拳 | J24: =LEN(_xlfn.IFNA(VLOOKUP(G24,特昇対策!$C:$C,1,FALSE),IF(OR(I24="龍王拳",I24="龍華拳",H24="二",H24="三",H24="四"),G24,""))) -> 8 | L24: 熊手返（片・両） | M24: 四 | N24: 龍華拳 | O24: =LEN(_xlfn.IFNA(VLOOKUP(L24,特昇対策!$C:$C,1,FALSE),IF(OR(N24="龍王拳",N24="龍華拳",M24="二",M24="三",M24="四"),L24,""))) -> 8 | Q24: 一本背投げ
B25: 切抜（内・外） | C25: 4 | D25: 龍王拳 | E25: =LEN(_xlfn.IFNA(VLOOKUP(B25,特昇対策!$C:$C,1,FALSE),IF(OR(D25="龍王拳",D25="龍華拳",C25="二",C25="三",C25="四"),B25,""))) -> 7 | G25: 押切抜 | H25: 2 | I25: 龍王拳 | J25: =LEN(_xlfn.IFNA(VLOOKUP(G25,特昇対策!$C:$C,1,FALSE),IF(OR(I25="龍王拳",I25="龍華拳",H25="二",H25="三",H25="四"),G25,""))) -> 3 | K25: 足系 | L25: 足抜（二種） | M25: 四 | N25: 龍王拳 | O25: =LEN(_xlfn.IFNA(VLOOKUP(L25,特昇対策!$C:$C,1,FALSE),IF(OR(N25="龍王拳",N25="龍華拳",M25="二",M25="三",M25="四"),L25,""))) -> 6 | Q25: 腕捻じ上げ
B26: 合掌抜 | C26: 2 | D26: 龍王拳 | E26: =LEN(_xlfn.IFNA(VLOOKUP(B26,特昇対策!$C:$C,1,FALSE),IF(OR(D26="龍王拳",D26="龍華拳",C26="二",C26="三",C26="四"),B26,""))) -> 3 | F26: 崩投 | G26: 表投 | H26: 四 | I26: 羅漢拳 | J26: =LEN(_xlfn.IFNA(VLOOKUP(G26,特昇対策!$C:$C,1,FALSE),IF(OR(I26="龍王拳",I26="龍華拳",H26="二",H26="三",H26="四"),G26,""))) -> 2
B27: 諸手引抜 | C27: 1 | D27: 龍王拳 | E27: =LEN(_xlfn.IFNA(VLOOKUP(B27,特昇対策!$C:$C,1,FALSE),IF(OR(D27="龍王拳",D27="龍華拳",C27="二",C27="三",C27="四"),B27,""))) -> 4 | G27: 裏投 | H27: 四 | I27: 羅漢拳 | J27: =LEN(_xlfn.IFNA(VLOOKUP(G27,特昇対策!$C:$C,1,FALSE),IF(OR(I27="龍王拳",I27="龍華拳",H27="二",H27="三",H27="四"),G27,""))) -> 2
A28: 切小手系 | B28: 切小手 | C28: 2 | D28: 龍華拳 | E28: =LEN(_xlfn.IFNA(VLOOKUP(B28,特昇対策!$C:$C,1,FALSE),IF(OR(D28="龍王拳",D28="龍華拳",C28="二",C28="三",C28="四"),B28,""))) -> 3 | G28: 矢筈投 | H28: 四 | I28: 羅漢拳 | J28: =LEN(_xlfn.IFNA(VLOOKUP(G28,特昇対策!$C:$C,1,FALSE),IF(OR(I28="龍王拳",I28="龍華拳",H28="二",H28="三",H28="四"),G28,""))) -> 3
B29: 切返小手 | C29: 三 | D29: 龍華拳 | E29: =LEN(_xlfn.IFNA(VLOOKUP(B29,特昇対策!$C:$C,1,FALSE),IF(OR(D29="龍王拳",D29="龍華拳",C29="二",C29="三",C29="四"),B29,""))) -> 4 | G29: 肩打投 | H29: 三 | I29: 羅漢拳 | J29: =LEN(_xlfn.IFNA(VLOOKUP(G29,特昇対策!$C:$C,1,FALSE),IF(OR(I29="龍王拳",I29="龍華拳",H29="二",H29="三",H29="四"),G29,""))) -> 3
B30: 切返投 | C30: 三 | D30: 龍華拳 | E30: =LEN(_xlfn.IFNA(VLOOKUP(B30,特昇対策!$C:$C,1,FALSE),IF(OR(D30="龍王拳",D30="龍華拳",C30="二",C30="三",C30="四"),B30,""))) -> 3 | F30: 首締投 | G30: 首締投 | H30: 四 | I30: 羅漢拳 | J30: =LEN(_xlfn.IFNA(VLOOKUP(G30,特昇対策!$C:$C,1,FALSE),IF(OR(I30="龍王拳",I30="龍華拳",H30="二",H30="三",H30="四"),G30,""))) -> 3
B31: 諸手切返投 | C31: 三 | D31: 龍華拳 | E31: =LEN(_xlfn.IFNA(VLOOKUP(B31,特昇対策!$C:$C,1,FALSE),IF(OR(D31="龍王拳",D31="龍華拳",C31="二",C31="三",C31="四"),B31,""))) -> 5 | G31: 首締守法十字投 | H31: 四 | I31: 羅漢拳 | J31: =LEN(_xlfn.IFNA(VLOOKUP(G31,特昇対策!$C:$C,1,FALSE),IF(OR(I31="龍王拳",I31="龍華拳",H31="二",H31="三",H31="四"),G31,""))) -> 7
B32: 切返天秤 | C32: 二 | D32: 龍華拳 | E32: =LEN(_xlfn.IFNA(VLOOKUP(B32,特昇対策!$C:$C,1,FALSE),IF(OR(D32="龍王拳",D32="龍華拳",C32="二",C32="三",C32="四"),B32,""))) -> 4 | G32: 拳締捕 | H32: 四 | I32: 羅漢拳 | J32: =LEN(_xlfn.IFNA(VLOOKUP(G32,特昇対策!$C:$C,1,FALSE),IF(OR(I32="龍王拳",I32="龍華拳",H32="二",H32="三",H32="四"),G32,""))) -> 3
B33: 切返巻天秤 | C33: 二 | D33: 龍華拳 | E33: =LEN(_xlfn.IFNA(VLOOKUP(B33,特昇対策!$C:$C,1,FALSE),IF(OR(D33="龍王拳",D33="龍華拳",C33="二",C33="三",C33="四"),B33,""))) -> 5 | F33: 一本背投げ | G33: 諸手輪抜 | H33: 初 | I33: 龍王拳 | J33: =LEN(_xlfn.IFNA(VLOOKUP(G33,特昇対策!$C:$C,1,FALSE),IF(OR(I33="龍王拳",I33="龍華拳",H33="二",H33="三",H33="四"),G33,""))) -> 4
B34: 切返抜（片・諸） | C34: 2 | D34: 龍王拳 | E34: =LEN(_xlfn.IFNA(VLOOKUP(B34,特昇対策!$C:$C,1,FALSE),IF(OR(D34="龍王拳",D34="龍華拳",C34="二",C34="三",C34="四"),B34,""))) -> 8 | G34: 諸手巻抜 | H34: 初 | I34: 龍王拳 | J34: =LEN(_xlfn.IFNA(VLOOKUP(G34,特昇対策!$C:$C,1,FALSE),IF(OR(I34="龍王拳",I34="龍華拳",H34="二",H34="三",H34="四"),G34,""))) -> 4
B35: 三角抜 | C35: 2 | D35: 龍王拳 | E35: =LEN(_xlfn.IFNA(VLOOKUP(B35,特昇対策!$C:$C,1,FALSE),IF(OR(D35="龍王拳",D35="龍華拳",C35="二",C35="三",C35="四"),B35,""))) -> 3 | G35: 諸手逆小手 | H35: 二 | I35: 龍華拳 | J35: =LEN(_xlfn.IFNA(VLOOKUP(G35,特昇対策!$C:$C,1,FALSE),IF(OR(I35="龍王拳",I35="龍華拳",H35="二",H35="三",H35="四"),G35,""))) -> 5
A36: 十字小手系 | B36: 十字小手（片・両・諸） | C36: 3・2・1 | D36: 龍華拳 | E36: =LEN(_xlfn.IFNA(VLOOKUP(B36,特昇対策!$C:$C,1,FALSE),IF(OR(D36="龍王拳",D36="龍華拳",C36="二",C36="三",C36="四"),B36,""))) -> 11 | G36: 諸手送小手 | H36: 二 | I36: 龍華拳 | J36: =LEN(_xlfn.IFNA(VLOOKUP(G36,特昇対策!$C:$C,1,FALSE),IF(OR(I36="龍王拳",I36="龍華拳",H36="二",H36="三",H36="四"),G36,""))) -> 5
B37: 略十字小手 | C37: 2 | D37: 龍華拳 | E37: =LEN(_xlfn.IFNA(VLOOKUP(B37,特昇対策!$C:$C,1,FALSE),IF(OR(D37="龍王拳",D37="龍華拳",C37="二",C37="三",C37="四"),B37,""))) -> 5 | G37: 振捨表投 | H37: 三 | I37: 龍華拳 | J37: =LEN(_xlfn.IFNA(VLOOKUP(G37,特昇対策!$C:$C,1,FALSE),IF(OR(I37="龍王拳",I37="龍華拳",H37="二",H37="三",H37="四"),G37,""))) -> 4
B38: 巻十字小手 | C38: 2 | D38: 龍華拳 | E38: =LEN(_xlfn.IFNA(VLOOKUP(B38,特昇対策!$C:$C,1,FALSE),IF(OR(D38="龍王拳",D38="龍華拳",C38="二",C38="三",C38="四"),B38,""))) -> 5 | G38: 諸手送小手投 | H38: 三 | I38: 龍華拳 | J38: =LEN(_xlfn.IFNA(VLOOKUP(G38,特昇対策!$C:$C,1,FALSE),IF(OR(I38="龍王拳",I38="龍華拳",H38="二",H38="三",H38="四"),G38,""))) -> 6
B39: 十字抜（片・両・諸） | C39: 3・2・1 | D39: 龍王拳 | E39: =LEN(_xlfn.IFNA(VLOOKUP(B39,特昇対策!$C:$C,1,FALSE),IF(OR(D39="龍王拳",D39="龍華拳",C39="二",C39="三",C39="四"),B39,""))) -> 10 | G39: 送突倒 | H39: 三 | I39: 龍華拳 | J39: =LEN(_xlfn.IFNA(VLOOKUP(G39,特昇対策!$C:$C,1,FALSE),IF(OR(I39="龍王拳",I39="龍華拳",H39="二",H39="三",H39="四"),G39,""))) -> 3
A40: 逆小手系 | B40: 逆小手前指固 | C40: 5 | D40: 金剛拳 | E40: =LEN(_xlfn.IFNA(VLOOKUP(B40,特昇対策!$C:$C,1,FALSE),IF(OR(D40="龍王拳",D40="龍華拳",C40="二",C40="三",C40="四"),B40,""))) -> 0 | G40: 腰挫 | H40: 三 | I40: 龍華拳 | J40: =LEN(_xlfn.IFNA(VLOOKUP(G40,特昇対策!$C:$C,1,FALSE),IF(OR(I40="龍王拳",I40="龍華拳",H40="二",H40="三",H40="四"),G40,""))) -> 2
...

Sheet 階級別まとめ
B1: 6級 | E1: ５級 | H1: ４級 | K1: 3級 | N1: 2級 | Q1: 1級 | T1: 初段 | W1: 二段 | Z1: 三段 | AC1: 四段
A2: 仁王拳
A3: □ | B3: 流水蹴（後） | C3: 対・開 | D3: □ | E3: 流水蹴（前） | F3: 対 | G3: □ | H3: 打上突（裏・表） | I3: 裏：対 表：開 | J3: □ | K3: 内受蹴（裏・表） | L3: 裏：対 表：開 | M3: □ | N3: 内受突（表） | O3: 開 | V3: □ | W3: 開身突（表・裏） | X3: 表：開 裏：対 | Y3: □ | Z3: 短刀振上げ流水蹴 | AA3: 対
A4: □ | B4: 転身蹴 | C4: 対 | D4: □ | E4: 上受蹴（表・裏） | F4: 対 | G4: □ | H4: 打上蹴（裏・表） | I4: 裏：対 表：開 | J4: □ | K4: 外押受突 | L4: 対 | M4: □ | N4: 外押受蹴 | O4: 対 | V4: □ | W4: 半月蹴 | X4: 対 | Y4: □ | Z4: 打上段突 | AA4: 裏：対 表：開
A5: □ | B5: 上受突（表・裏） | C5: 対 | G5: □ | H5: 外受突（裏・表） | I5: 裏：対 表：開 | J5: □ | K5: 内押受突 | L5: 開 | M5: □ | N5: 内押受蹴 | O5: 開 | Y5: □ | Z5: 外受段突 | AA5: 裏：対 表：開
A6: □ | B6: 内受突（裏） | C6: 対 | G6: □ | H6: 外受蹴（裏・表） | I6: 裏：対 表：開 | M6: □ | N6: 屈身突 | O6: 対 | Y6: □ | Z6: 下受突 | AA6: 対
M7: □ | N7: 屈身蹴 | O7: 対 | Y7: □ | Z7: 下受段突 | AA7: 対
M8: □ | N8: 屈身突蹴 | O8: 対 | Y8: □ | Z8: 短刀突込み下受打落蹴 | AA8: 対
Y9: □ | Z9: 待ち蹴
A10: 三合拳
D11: □ | E11: 下受蹴 | F11: 対 | J11: □ | K11: 十字受蹴 | L11: 対 | M11: □ | N11: 半転身蹴 | O11: 開 | P11: □ | Q11: 払受蹴 | R11: 開 | S11: □ | T11: 逆転身蹴 | U11: 開 | Y11: □ | Z11: 中段返 | AA11: 開
D12: □ | E12: 下受順蹴 | F12: 対 | M12: □ | N12: 横転身蹴 | O12: 対 | S12: □ | T12: 下段返 | U12: 開
A13: 天王拳
J14: □ | K14: 突天一 | L14: 開 | M14: □ | N14: 混天一 | O14: 開 | P14: □ | Q14: 振天二 | R14: 開 | V14: □ | W14: 対天一 | X14: 対 | Y14: □ | Z14: 蹴天一 | AA14: 対
P15: □ | Q15: 突天二 | R15: 開 | V15: □ | W15: 逆天一 | X15: 開
P16: □ | Q16: 突天三 | R16: 開
P17: □ | Q17: 蹴天三 | R17: 開
A18: 白蓮拳
P19: □ | Q19: 燕返 | R19: 開 | V19: □ | W19: 払受段月 | X19: 開 | Y19: □ | Z19: 半月返 | AA19: 対
P20: □ | Q20: 千鳥返 | R20: 対 | Y20: □ | Z20: 水月返 | AA20: 対
Y21: □ | Z21: 三日月返 | AA21: 対
A22: 地王拳
V23: □ | W23: 順蹴地一 | X23: 対 | Y23: □ | Z23: 伏虎地二
V24: □ | W24: 逆蹴地一 | X24: 開
V25: □ | W25: 払受地二
V26: □ | W26: 順蹴地三 | X26: 開
V27: □ | W27: 逆蹴地三 | X27: 開
A28: 鶴立拳
S29: □ | T29: 金的蹴膝受波返 | U29: 対 | V29: □ | W29: 足刀蹴引足波返 | X29: 対
S30: □ | T30: 逆蹴膝受波返 | U30: 開 | V30: □ | W30: 廻蹴三防受波返 | X30: 対
V31: □ | W31: 段蹴三防受段蹴返 | X31: 対
A32: 龍王拳
A33: □ | B33: 小手抜 | C33: 対・開 | D33: □ | E33: 巻抜（片手） | F33: 開 | G33: □ | H33: 突抜（外・内） | I33: 外：開 内：対 | J33: □ | K33: 突抜（両手） | L33: 対 | M33: □ | N33: 十字抜（両手） | O33: 対 | P33: □ | Q33: 諸手突抜 | R33: 開 | S33: □ | T33: 諸手押抜 | U33: 対 | V33: □ | W33: 打抜（片手・両手） | X33: 片：開 両：対 | Y33: □ | Z33: 上げ抜 | AB33: □ | AC33: 足抜（二種）
D34: □ | E34: 片手寄抜 | F34: 開 | G34: □ | H34: 切抜（外・内） | I34: 外：開 内：対 | J34: □ | K34: 巻抜（両手） | L34: 対 | M34: □ | N34: 合掌抜 | O34: 対 | P34: □ | Q34: 諸手十字抜 | R34: 逆手：開 腕逆捕：対 | S34: □ | T34: 諸手巻抜 | U34: 開
J35: □ | K35: 両手寄抜 | L35: 対 | M35: □ | N35: 切返抜（諸手・片手） | O35: 対 | P35: □ | Q35: 片手押抜 | R35: 開 | S35: □ | T35: 諸手輪抜 | U35: 開
J36: □ | K36: 二段抜 | L36: 対 | M36: □ | N36: 三角抜 | O36: 対 | P36: □ | Q36: 諸手引抜 | R36: 対
J37: □ | K37: 肘抜より前天秤 | L37: 対 | M37: □ | N37: 上膊抜（片手・両手） | O37: 片：開 両：対 | P37: □ | Q37: 襟抜
J38: □ | K38: 十字抜（片手） | L38: 開 | M38: □ | N38: 押切抜 | O38: 対 | P38: □ | Q38: 袖抜
A39: 龍華拳
D40: □ | E40: 逆小手 | F40: 対・開 | G40: □ | H40: 片手送小手 | I40: 開 | J40: □ | K40: 逆小手より裏返投 | L40: 対 | M40: □ | N40: 両手送小手 | O40: 対 | P40: □ | Q40: 諸手十字小手 | R40: 逆手：開 腕逆捕：対 | S40: □ | T40: 押小手（片手・両手） | U40: 片：開 両：対 | V40: □ | W40: 逆手投 | X40: 対 | Y40: □ | Z40: 居捕逆小手 | AB40: □ | AC40: 合掌逆小手
...

Sheet まとめ
A1: 拳系 | D1: 6級 | G1: ５級 | J1: ４級 | M1: 3級 | P1: 2級 | S1: 1級 | V1: 初段 | Y1: 二段 | AB1: 三段 | AE1: 四段 | AI1: =COUNTA(Y2:Y180) -> 42 | AJ1: =COUNTA(AB2:AB180) -> 46 | AK1: =COUNTA(AE2:AE180) -> 32 | AM1: 拳系 | AP1: 二～四
A2: 仁王拳 | B2: 上段逆突又は手刀打込 体捌きだけでかわす | C2: □ | D2: 流水蹴（後） | E2: 対・開 | F2: □ | G2: 流水蹴（前） | H2: 対 | AA2: □ | AB2: 短刀振上げ流水蹴 | AC2: 対 | AI2: =COUNTA(Y2:Y52) -> 13 | AJ2: =COUNTA(AB2:AB52) -> 13 | AK2: =COUNTA(AE2:AE52) -> 0 | AM2: 仁王拳 | AN2: =COUNTA(D2:D20,G2:G20,J2:J20,M2:M20,P2:P20,S2:S20,V2:V20,Y2:Y20,AB2:AB20,AE2:AE20) -> 28 | AP2: =COUNTA(Y2:Y20,AB2:AB20,AE2:AE20) -> 9
B3: 上段逆突 横に足捌き | C3: □ | D3: 転身蹴 | E3: 対 | AI3: =COUNTA(Y53:Y180) -> 29 | AJ3: =COUNTA(AB53:AB180) -> 33 | AK3: =COUNTA(AE53:AE180) -> 32 | AL3: ● | AM3: 三合拳 | AN3: =COUNTA(D21:D28,G21:G28,J21:J28,M21:M28,P21:P28,S21:S28,V21:V28,Y21:Y28,AB21:AB28,AE21:AE28) -> 9 | AP3: =COUNTA(Y21:Y28,AB21:AB28,AE21:AE28) -> 1
B4: 手刀打 腕刀で受ける | C4: □ | D4: 上受突（表・裏） | E4: 対 | F4: □ | G4: 上受蹴（表・裏） | H4: 対 | AL4: ● | AM4: 天王拳 | AN4: =COUNTA(D29:D36,G29:G36,J29:J36,M29:M36,P29:P36,S29:S36,V29:V36,Y29:Y36,AB29:AB36,AE29:AE36) -> 9 | AP4: =COUNTA(Y29:Y36,AB29:AB36,AE29:AE36) -> 3
B5: 上段逆突 腕刀で受ける | C5: □ | D5: 内受突（裏） | E5: 対 | L5: □ | M5: 内受蹴（裏・表） | N5: 裏：対 表：開 | O5: □ | P5: 内受突（表） | Q5: 開 | AL5: ● | AM5: 白連拳 | AN5: =COUNTA(D37:D42,G37:G42,J37:J42,M37:M42,P37:P42,S37:S42,V37:V42,Y37:Y42,AB37:AB42,AE37:AE42) -> 6 | AP5: =COUNTA(Y37:Y42,AB37:AB42,AE37:AE42) -> 4
B6: 上段逆突 握拳打上 | I6: □ | J6: 打上突（裏・表） | K6: 裏：対 表：開 | AA6: □ | AB6: 打上段突 | AC6: 裏：対 表：開 | AL6: ● | AM6: 地王拳 | AN6: =COUNTA(D43:D47,G43:G47,J43:J47,M43:M47,P43:P47,S43:S47,V43:V47,Y43:Y47,AB43:AB47,AE43:AE47) -> 6 | AP6: =COUNTA(Y43:Y47,AB43:AB47,AE43:AE47) -> 6
I7: □ | J7: 打上蹴（裏・表） | K7: 裏：対 表：開 | AL7: ● | AM7: 鶴立拳 | AN7: =COUNTA(D48:D52,G48:G52,J48:J52,M48:M52,P48:P52,S48:S52,V48:V52,Y48:Y52,AB48:AB52,AE48:AE52) -> 5 | AP7: =COUNTA(Y48:Y52,AB48:AB52,AE48:AE52) -> 3
B8: 上段振突 屈身と流水 | O8: □ | P8: 屈身突 | Q8: 対 | AL8: ● | AM8: 龍王拳 | AN8: =COUNTA(D53:D75,G53:G75,J53:J75,M53:M75,P53:P75,S53:S75,V53:V75,Y53:Y75,AB53:AB75,AE53:AE75) -> 29 | AP8: =COUNTA(Y53:Y75,AB53:AB75,AE53:AE75) -> 3
O9: □ | P9: 屈身蹴 | Q9: 対 | AL9: ● | AM9: 龍華拳 | AN9: =COUNTA(D76:D111,G76:G111,J76:J111,M76:M111,P76:P111,S76:S111,V76:V111,Y76:Y111,AB76:AB111,AE76:AE111) -> 50 | AP9: =COUNTA(Y76:Y111,AB76:AB111,AE76:AE111) -> 34
O10: □ | P10: 屈身突蹴 | Q10: 対 | AM10: 五花拳 | AN10: =COUNTA(D112:D126,G112:G126,J112:J126,M112:M126,P112:P126,S112:S126,V112:V126,Y112:Y126,AB112:AB126,AE112:AE126) -> 17 | AP10: =COUNTA(Y112:Y126,AB112:AB126,AE112:AE126) -> 16
B11: 上段逆突 後ろ手腕刀で受ける | I11: □ | J11: 外受突（裏・表） | K11: 裏：対 表：開 | AA11: □ | AB11: 外受段突 | AC11: 裏：対 表：開 | AM11: 金剛拳 | AN11: =COUNTA(D127:D150,G127:G150,J127:J150,M127:M150,P127:P150,S127:S150,V127:V150,Y127:Y150,AB127:AB150,AE127:AE1482) -> 42 | AP11: =COUNTA(Y127:Y150,AB127:AB150,AE127:AE150) -> 17
I12: □ | J12: 外受蹴（裏・表） | K12: 裏：対 表：開 | AM12: 羅漢拳 | AN12: =COUNTA(D151:D180,G151:G180,J151:J180,M151:M180,P151:P180,S151:S180,V151:V180,Y151:Y180,AB151:AB180,AE151:AE180) -> 32 | AP12: =COUNTA(Y151:Y180,AB151:AB180,AE151:AE180) -> 24
B13: 振突 腕刀で押し受ける | L13: □ | M13: 外押受突 | N13: 対 | O13: □ | P13: 外押受蹴 | Q13: 対
L14: □ | M14: 内押受突 | N14: 開 | O14: □ | P14: 内押受蹴 | Q14: 開
B15: 上段逆突 半月受 | X15: □ | Y15: 開身突（表・裏） | Z15: 表：開 裏：対
X16: □ | Y16: 半月蹴 | Z16: 対
B17: 中段逆突 八相構えで下受 | AA17: □ | AB17: 下受突 | AC17: 対
AA18: □ | AB18: 下受段突 | AC18: 対
AA19: □ | AB19: 短刀突込み下受打落蹴 | AC19: 対
B20: 同時蹴り | AA20: □ | AB20: 待ち蹴
A21: 三合拳 | B21: 中段逆突 八相構えで下受 | F21: □ | G21: 下受蹴 | H21: 対
F22: □ | G22: 下受順蹴 | H22: 対
B23: 中段逆蹴・差替中段順突 転身してかわす | O23: □ | P23: 半転身蹴 | Q23: 開 | U23: □ | V23: 逆転身蹴 | W23: 開
O24: □ | P24: 横転身蹴 | Q24: 対
B25: 中段廻蹴 打払受＋打押受 | L25: □ | M25: 十字受蹴 | N25: 対
B26: 中段廻蹴 打払受 | R26: □ | S26: 払受蹴 | T26: 開
B27: 差込蹴 打払受して蹴込 | U27: □ | V27: 下段返 | W27: 開
B28: 差込蹴 体をひねり乍ら下受して蹴込 | AA28: □ | AB28: 中段返 | AC28: 開
A29: 天王拳 | B29: 上段順突＋中段逆突（二連攻） | L29: □ | M29: 突天一 | N29: 開 | X29: □ | Y29: 対天一 | Z29: 対
B30: 上段逆突＋中段順突（二連攻） | X30: □ | Y30: 逆天一 | Z30: 開
B31: 横振突＋中段順突（二連攻） | O31: □ | P31: 混天一 | Q31: 開
B32: 振突＋逆振突（二連攻） | R32: □ | S32: 振天二 | T32: 開
B33: 上段順突＋上段逆突（二連攻） | R33: □ | S33: 突天二 | T33: 開
B34: 上段順突＋中段逆突＋差込上段順突（三連攻） | R34: □ | S34: 突天三 | T34: 開
B35: 上段逆突＋中段廻蹴（二連攻） | AA35: □ | AB35: 蹴天一 | AC35: 対
B36: 上段順突＋中段逆突＋中段廻蹴（三連攻） | R36: □ | S36: 蹴天三 | T36: 開
A37: 白連拳 | B37: 差込上段逆突 | R37: □ | S37: 燕返 | T37: 開
R38: □ | S38: 千鳥返 | T38: 対
B39: 差込中段廻蹴 | X39: □ | Y39: 払受段月 | Z39: 開
B40: 上段順突＋中段逆突（二連攻） 乱構 | AA40: □ | AB40: 半月返 | AC40: 対
...

Sheet 仁王拳
B1: 仁王拳 | D1: 構/守/攻 | E1: 攻撃 | F1: 教範 | G1: はじめよう！ | H1: ー愛の価値
A2: =ROW()-1 -> 1 | B2: 流水蹴(前) | C2: ⑤ | F2: 170 | G2: 52 | H2: 84
A3: =ROW()-1 -> 2 | B3: 流水蹴(後) | C3: ⑥ | D3: 対・開/一/中 | E3: 上逆 | F3: 170 | G3: 50 | H3: 86
A4: =ROW()-1 -> 3 | B4: 上受突(表) | C4: ⑥ | D4: 対/一/中 | E4: 手打 | F4: 171 | G4: 58 | H4: 92
A5: =ROW()-1 -> 4 | B5: 上受突(裏) | C5: ⑥ | D5: 対/一/中 | E5: 手打 | F5: 171
A6: =ROW()-1 -> 5 | B6: 上受蹴(表) | C6: ⑤ | D6: 対/一/中 | E6: 手打 | F6: 172
A7: =ROW()-1 -> 6 | B7: 上受蹴(裏) | C7: ⑤ | D7: 対/一/中 | E7: 手打 | F7: 172 | G7: 56 | H7: 90
A8: =ROW()-1 -> 7 | B8: 打上突(表) | C8: ④ | D8: 開/一/中 | E8: 上直 | F8: 172
A9: =ROW()-1 -> 8 | B9: 打上突(裏) | C9: ④ | D9: 対/一/中 | E9: 上直 | F9: 172
A10: =ROW()-1 -> 9 | B10: 打上蹴(表) | C10: ④ | D10: 開/一/中 | E10: 上直 | F10: 173
A11: =ROW()-1 -> 10 | B11: 打上蹴(裏) | C11: ④ | D11: 対/一/中 | E11: 上直 | F11: 173
A12: =ROW()-1 -> 11 | B12: 内受突(表) | C12: ② | D12: 開/一/中 | E12: 上直 | F12: 173
A13: =ROW()-1 -> 12 | B13: 内受突(裏) | C13: ⑥ | D13: 対/一/中 | E13: 上直 | F13: 173 | G13: 54 | H13: 88
A14: =ROW()-1 -> 13 | B14: 内受蹴(表) | C14: ③ | D14: 開/一/中 | E14: 上直 | F14: 174 | G14: 68 | H14: 96
A15: =ROW()-1 -> 14 | B15: 内受蹴(裏) | C15: ③ | D15: 対/一/中 | E15: 上直 | F15: 174
A16: =ROW()-1 -> 15 | B16: 外受突(表) | C16: ④ | D16: 開/一/中 | E16: 上直 | F16: 174
A17: =ROW()-1 -> 16 | B17: 外受突(裏) | C17: ④ | D17: 対/一/中 | E17: 上直 | F17: 174 | G17: 80 | H17: 98
A18: =ROW()-1 -> 17 | B18: 外受蹴(表) | C18: ④ | D18: 開/一/中 | E18: 上直 | F18: 175
A19: =ROW()-1 -> 18 | B19: 外受蹴(裏) | C19: ④ | D19: 対/一/中 | E19: 上直 | F19: 175 | G19: 81 | H19: 100
A20: =ROW()-1 -> 19 | B20: 外押受突 | C20: ③ | D20: 対/一/中 | E20: 上横振突 | F20: 175 | G20: 82 | H20: 101
A21: =ROW()-1 -> 20 | B21: 外押受蹴 | C21: ② | D21: 対/一/中 | E21: 上横振突 | F21: 175
A22: =ROW()-1 -> 21 | B22: 内押受突 | C22: ③ | D22: 開/一/中 | E22: 上横振突 | F22: 175
A23: =ROW()-1 -> 22 | B23: 内押受蹴 | C23: ② | D23: 開/一/中 | E23: 上横振突
A24: =ROW()-1 -> 23 | B24: 開身突(表) | C24: 二 | D24: 開/乱/中 | E24: 上逆 | F24: 176 | H24: 104
A25: =ROW()-1 -> 24 | B25: 開身突(裏) | C25: 二 | D25: 対/乱/中 | E25: 上逆 | F25: 176
A26: =ROW()-1 -> 25 | B26: 転身蹴 | C26: ⑥ | D26: 対・開/一/中 | E26: 上直 | F26: 176 | G26: 66 | H26: 94
A27: =ROW()-1 -> 26 | B27: 屈身突 | C27: ② | D27: 対/一/中 | E27: 上横振突 | F27: 176 | G27: 84 | H27: 102
A28: =ROW()-1 -> 27 | B28: 屈身蹴 | C28: ② | D28: 対/一/中 | E28: 上横振突 | F28: 176 | G28: 84 | H28: 103
A29: =ROW()-1 -> 28 | B29: 屈身突蹴 | C29: ② | D29: 対/一/中 | E29: 上横振突
A30: =ROW()-1 -> 29 | B30: 半月蹴 | C30: 二 | D30: 対/乱/中 | E30: 上逆 | F30: 177 | H30: 107
A31: =ROW()-1 -> 30 | B31: 待ち蹴 | C31: 三 | D31: 開/一/中 | E31: 上逆 | F31: 177
A32: =ROW()-1 -> 31 | B32: 下受突 | C32: 三 | D32: 対/八/中 | E32: 中逆 | F32: 177 | G32: 58 | H32: 105
A33: =ROW()-1 -> 32 | B33: 下受段突 | C33: 三 | D33: 対/八/中 | E33: 中逆 | F33: 177 | H33: 106
A34: =ROW()-1 -> 33 | B34: 外受段突 | C34: 三 | D34: 対/一/中 | E34: 上逆 | F34: 178 | H34: 99
A35: =ROW()-1 -> 34 | B35: 打上段突 | C35: 三 | D35: 対/一/中 | E35: 上逆 | F35: 178
A36: =ROW()-1 -> 35 | B36: 短刀突込み下受打落蹴 | C36: 三 | D36: 対/八/中 | E36: 突込 | F36: 179
A37: =ROW()-1 -> 36 | B37: 短刀振上げ流水蹴 | C37: 三 | D37: 開/一/中 | E37: 振上

Sheet 三合拳～地王拳
B1: 三合拳 | D1: 構/守/攻 | E1: 攻撃 | F1: 教範 | G1: はじめよう！ | H1: ー愛の価値
A2: =ROW()-1 -> 1 | B2: 払受蹴 | C2: ① | D2: 開/一/一 | E2: 込廻 | F2: 180
A3: =ROW()-1 -> 2 | B3: 下段返 | C3: 初 | D3: 開/一/一 | E3: 込廻 | F3: 180 | H3: 116
A4: =ROW()-1 -> 3 | B4: 中段返 | C4: 三 | D4: 開/待/一 | E4: 込廻 | F4: 180 | H4: 118
A5: =ROW()-1 -> 4 | B5: 下受蹴 | C5: ⑤ | D5: 対/八/中 | E5: 中逆 | F5: 182 | G5: 60 | H5: 109
A6: =ROW()-1 -> 5 | B6: 下受順蹴 | C6: ⑤ | D6: 対/八/中 | E6: 中順 | F6: 182 | G6: 62 | H6: 110
A7: =ROW()-1 -> 6 | B7: 逆転身蹴 | C7: 初 | D7: 開/八/一 | E7: 替中 | F7: 183 | G7: 72
A8: =ROW()-1 -> 7 | B8: 半転身蹴 | C8: ② | D8: 開/中/一 | E8: 中逆 | F8: 183 | H8: 114
A9: =ROW()-1 -> 8 | B9: 横転身蹴 | C9: ② | D9: 対/中/一 | E9: 中逆 | F9: 183 | G9: 70 | H9: 112
A10: =ROW()-1 -> 9 | B10: 十字受蹴 | C10: ③ | D10: 対/一/一 | E10: 込廻 | F10: 183 | G10: 74 | H10: 108
B12: 天王拳 | D12: 構/守/攻 | E12: 攻撃 | F12: 教範 | G12: はじめよう！ | H12: ー愛の価値
A13: =ROW()-12 -> 1 | B13: 突天一 | C13: ③ | D13: 開/一/中 | E13: 上順突・中逆突 | F13: 185 | G13: 64 | H13: 120
A14: =ROW()-12 -> 2 | B14: 蹴天一 | C14: 三 | D14: 開/一/中 | E14: 上逆 | F14: 186
A15: =ROW()-12 -> 3 | B15: 逆天一 | C15: 二 | D15: 開/一/中 | E15: 上逆 | F15: 187 | H15: 127
A16: =ROW()-12 -> 4 | B16: 振天二 | C16: ① | D16: 開/一/一 | E16: 横振・上振 | F16: 188
A17: =ROW()-12 -> 5 | B17: 突天二 | C17: ① | D17: 開/中/中 | E17: 上順突・中逆突 | F17: 188
A18: =ROW()-12 -> 6 | B18: 蹴天三 | C18: ① | D18: 開/一/中 | E18: 上順突・中逆突・中逆蹴 | F18: 189 | H18: 122
A19: =ROW()-12 -> 7 | B19: 突天三 | C19: ① | D19: 開/一/中 | E19: 上順突・中逆突・上順突 | F19: 189 | H19: 124
A20: =ROW()-12 -> 8 | B20: 混天一 | C20: ② | D20: 開/一/一 | E20: 上横振・中逆突 | F20: 190
A21: =ROW()-12 -> 9 | B21: 対天一 | C21: 二 | D21: 対/一/中 | E21: 上順 | F21: 191 | H21: 126
B23: 白蓮拳 | D23: 構/守/攻 | E23: 攻撃 | F23: 教範 | G23: はじめよう！ | H23: ー愛の価値
A24: =ROW()-23 -> 1 | B24: 燕返 | C24: ① | D24: 開/待/中 | E24: 上直突 | F24: 193 | G24: 76 | H24: 130
A25: =ROW()-23 -> 2 | B25: 千鳥返 | C25: ① | D25: 対/待/中 | E25: 替上順突 | F25: 193 | G25: 78 | H25: 128
A26: =ROW()-23 -> 3 | B26: 半月返・掬首投 | C26: 三 | D26: 対/乱/中 | E26: 上中 | F26: 194 | H26: 131
A27: =ROW()-23 -> 4 | B27: 払受段突 | C27: 二 | D27: 開/一/一 | E27: 込廻 | F27: 194 | H27: 132
A28: =ROW()-23 -> 5 | B28: 水月返 | C28: 三 | D28: 対/待/中 | E28: 上逆 | F28: 194 | H28: 136
A29: =ROW()-23 -> 6 | B29: 三日月返・刈足 | C29: 三 | D29: 対/待/中 | E29: 替上 | F29: 194 | H29: 134
B31: 地王拳 | D31: 構/守/攻 | E31: 攻撃 | F31: 教範 | G31: はじめよう！ | H31: ー愛の価値
A32: =ROW()-31 -> 1 | B32: 順蹴地一 | C32: 二 | D32: 対/一/一 | E32: 蛇金 | F32: 195 | H32: 138
A33: =ROW()-31 -> 2 | B33: 逆蹴地一 | C33: 二 | D33: 開/一/一 | E33: 蛇金 | F33: 196
A34: =ROW()-31 -> 3 | B34: 伏虎地二 | C34: 三 | D34: ・/座/一 | E34: 込廻 | F34: 196 | H34: 140
A35: =ROW()-31 -> 4 | B35: 払受地二 | C35: 二 | D35: 開/結/一 | E35: 込廻 | F35: 197 | H35: 142
A36: =ROW()-31 -> 5 | B36: 順蹴地三 | C36: 二 | D36: 開/一/一 | E36: 込廻 | F36: 198 | H36: 144
A37: =ROW()-31 -> 6 | B37: 逆蹴地三 | C37: 二 | D37: 開/一/中 | E37: 金的 | F37: 199

Sheet 三合拳
B1: 三合拳 | D1: 構/守/攻 | E1: 攻撃 | F1: 教範 | G1: はじめよう！ | H1: ー愛の価値
A2: =ROW()-1 -> 1 | B2: 払受蹴 | C2: ① | D2: 開/一/一 | E2: 込廻 | F2: 180
A3: =ROW()-1 -> 2 | B3: 下段返 | C3: 初 | D3: 開/一/一 | E3: 込廻 | F3: 180 | H3: 116
A4: =ROW()-1 -> 3 | B4: 中段返 | C4: 三 | D4: 開/待/一 | E4: 込廻 | F4: 180 | H4: 118
A5: =ROW()-1 -> 4 | B5: 下受蹴 | C5: ⑤ | D5: 対/八/中 | E5: 中逆 | F5: 182 | G5: 60 | H5: 109
A6: =ROW()-1 -> 5 | B6: 下受順蹴 | C6: ⑤ | D6: 対/八/中 | E6: 中順 | F6: 182 | G6: 62 | H6: 110
A7: =ROW()-1 -> 6 | B7: 逆転身蹴 | C7: 初 | D7: 開/八/一 | E7: 替中突 | F7: 183 | G7: 72
A8: =ROW()-1 -> 7 | B8: 半転身蹴 | C8: ② | D8: 開/中/一 | E8: 中逆蹴 | F8: 183 | H8: 114
A9: =ROW()-1 -> 8 | B9: 横転身蹴 | C9: ② | D9: 対/中/一 | E9: 中逆蹴 | F9: 183 | G9: 70 | H9: 112
A10: =ROW()-1 -> 9 | B10: 十字受蹴 | C10: ③ | D10: 対/一/一 | E10: 込廻 | F10: 183 | G10: 74 | H10: 108

Sheet 天王拳
B1: 天王拳 | D1: 構/守/攻 | E1: 攻撃 | F1: 教範 | G1: はじめよう！ | H1: ー愛の価値
A2: =ROW()-1 -> 1 | B2: 突天一 | C2: ③ | D2: 開/一/中 | E2: 上順突・中逆突 | F2: 185 | G2: 64 | H2: 120
A3: =ROW()-1 -> 2 | B3: 蹴天一 | C3: 三 | D3: 対/一/中 | E3: 上逆 | F3: 186
A4: =ROW()-1 -> 3 | B4: 逆天一 | C4: 二 | D4: 開/一/中 | E4: 上逆 | F4: 187 | H4: 127
A5: =ROW()-1 -> 4 | B5: 振天二 | C5: ① | D5: 開/一/一 | E5: 横振・上振 | F5: 188
A6: =ROW()-1 -> 5 | B6: 突天二 | C6: ① | D6: 開/中/中 | E6: 上順突・中逆突 | F6: 188
A7: =ROW()-1 -> 6 | B7: 蹴天三 | C7: ① | D7: 開/一/中 | E7: 上順突・中逆突・中逆蹴 | F7: 189 | H7: 122
A8: =ROW()-1 -> 7 | B8: 突天三 | C8: ① | D8: 開/一/中 | E8: 上順突・中逆突・上順突 | F8: 189 | H8: 124
A9: =ROW()-1 -> 8 | B9: 混天一 | C9: ② | D9: 開/一/一 | E9: 上横振・中逆突 | F9: 190
A10: =ROW()-1 -> 9 | B10: 対天一 | C10: 二 | D10: 対/一/中 | E10: 上順 | F10: 191 | H10: 126

Sheet 白蓮拳
B1: 白蓮拳 | D1: 構/守/攻 | E1: 攻撃 | F1: 教範 | G1: はじめよう！ | H1: ー愛の価値
A2: =ROW()-1 -> 1 | B2: 燕返 | C2: ① | D2: 開/待/中 | E2: 上直突 | F2: 193 | G2: 76 | H2: 130
A3: =ROW()-1 -> 2 | B3: 千鳥返 | C3: ① | D3: 対/待/中 | E3: 替上順突 | F3: 193 | G3: 78 | H3: 128
A4: =ROW()-1 -> 3 | B4: 半月返・掬首投 | C4: 三 | D4: 対/乱/中 | E4: 上中 | F4: 194 | H4: 131
A5: =ROW()-1 -> 4 | B5: 払受段突 | C5: 二 | D5: 開/一/一 | E5: 込廻 | F5: 194 | H5: 132
A6: =ROW()-1 -> 5 | B6: 水月返 | C6: 三 | D6: 対/待/中 | E6: 上逆 | F6: 194 | H6: 136
A7: =ROW()-1 -> 6 | B7: 三日月返・刈足 | C7: 三 | D7: 対/待/中 | E7: 替上 | F7: 194 | H7: 134

Sheet 地王拳
B1: 地王拳 | D1: 構/守/攻 | E1: 攻撃 | F1: 教範 | G1: はじめよう！ | H1: ー愛の価値
A2: =ROW()-1 -> 1 | B2: 順蹴地一 | C2: 二 | D2: 対/一/一 | E2: 蛇金 | F2: 195 | H2: 138
A3: =ROW()-1 -> 2 | B3: 逆蹴地一 | C3: 二 | D3: 開/一/一 | E3: 蛇金 | F3: 196
A4: =ROW()-1 -> 3 | B4: 伏虎地二 | C4: 三 | D4: ・/座/一 | E4: 込廻 | F4: 196 | H4: 140
A5: =ROW()-1 -> 4 | B5: 払受地二 | C5: 二 | D5: 開/結/一 | E5: 込廻 | F5: 197 | H5: 142
A6: =ROW()-1 -> 5 | B6: 順蹴地三 | C6: 二 | D6: 開/一/一 | E6: 込廻 | F6: 198 | H6: 144
A7: =ROW()-1 -> 6 | B7: 逆蹴地三 | C7: 二 | D7: 開/一/中 | E7: 金的 | F7: 199

Sheet 鶴立拳
B1: 鶴立拳 | D1: 構/守/攻 | E1: 攻撃 | F1: 教範 | G1: はじめよう！ | H1: ー愛の価値
A2: =ROW()-1 -> 1 | B2: 金的蹴膝受波返 | C2: 初 | D2: 対/一/一 | E2: 下金順蹴 | F2: 200 | H2: 146
A3: =ROW()-1 -> 2 | B3: 逆蹴膝受波返 | C3: 初 | D3: 開/一/一 | E3: 下金逆蹴 | F3: 200
A4: =ROW()-1 -> 3 | B4: 足刀蹴引足波返 | C4: 二 | D4: 対/一/一 | E4: 刈足 | F4: 200 | H4: 148
A5: =ROW()-1 -> 4 | B5: 廻蹴三防受波返 | C5: 二 | D5: 対/一/一 | E5: 高廻 | F5: 200 | H5: 147
A6: =ROW()-1 -> 5 | B6: 段蹴三防受段蹴返 | C6: 二 | D6: 対/一/一 | E6: 段蹴 | F6: 201 | H6: 150

Sheet 龍王拳
B1: 龍王拳 | D1: 構/守/攻 | E1: 攻撃 | F1: 教範 | G1: はじめよう！ | H1: ー愛の価値
A2: =ROW()-1 -> 1 | B2: 小手抜 | C2: ➅ | D2: 対/中/中 | F2: 213 | G2: 88 | H2: 152
A3: =ROW()-1 -> 2 | B3: 片手寄抜 | C3: ➄ | D3: 開/中/中 | H3: 162
A4: =ROW()-1 -> 3 | B4: 両手寄抜 | C4: ➂ | D4: 対/中/中 | F4: 218 | G4: 94
A5: =ROW()-1 -> 4 | B5: 突抜(両手) | C5: ➂ | D5: 対/中/・ | F5: 220
A6: =ROW()-1 -> 5 | B6: 突抜(外) | C6: ➃ | D6: 開/中/・
A7: =ROW()-1 -> 6 | B7: 突抜(内) | C7: ➃ | D7: 対/中/・
A8: =ROW()-1 -> 7 | B8: 諸手突抜 | C8: ➀ | D8: 開/中/中 | F8: 221
A9: =ROW()-1 -> 8 | B9: 巻抜(両手) | C9: ➂ | D9: 対/中/中 | F9: 221
A10: =ROW()-1 -> 9 | B10: 巻抜(片手) | C10: ➄ | D10: 開/中/中 | G10: 96 | H10: 164
A11: =ROW()-1 -> 10 | B11: 諸手巻抜 | C11: 初 | D11: 開/中/中 | F11: 222
A12: =ROW()-1 -> 11 | B12: 上げ抜 | C12: 三 | D12: ・/正/中 | F12: 222
A13: =ROW()-1 -> 12 | B13: 片手押抜 | C13: ➀ | D13: 開/下/中 | F13: 223 | H13: 208
A14: =ROW()-1 -> 13 | B14: 諸手押抜 | C14: 初 | D14: 対/中/中 | F14: 223
A15: =ROW()-1 -> 14 | B15: 切抜(外) | C15: ➃ | D15: 開/中/中 | F15: 223 | G15: 140
A16: =ROW()-1 -> 15 | B16: 切抜(内) | C16: ➃ | D16: 対/中/中
A17: =ROW()-1 -> 16 | B17: 十字抜(片手) | C17: ➂ | D17: 開/中/中 | F17: 224 | H17: 178
A18: =ROW()-1 -> 17 | B18: 十字抜(両手) | C18: ➁ | D18: 対/中/中 | G18: 104
A19: =ROW()-1 -> 18 | B19: 諸手十字抜 | C19: ➀ | D19: 開/中/中 | F19: 224
A20: =ROW()-1 -> 19 | B20: 合掌抜 | C20: ➁ | D20: 対/中/中 | F20: 225 | G20: 106
A21: =ROW()-1 -> 20 | B21: 二段抜 | C21: ➂ | D21: 開/中/中 | F21: 225 | H21: 204
A22: =ROW()-1 -> 21 | B22: 肘抜より前天秤 | C22: ➂ | D22: 開/中/中 | F22: 225 | H22: 176
A23: =ROW()-1 -> 22 | B23: 諸手引抜 | C23: ➀ | D23: 開/中/中 | F23: 226
A24: =ROW()-1 -> 23 | B24: 諸手輪抜 | C24: 初 | D24: 開/中/中 | F24: 226
A25: =ROW()-1 -> 24 | B25: 上膊抜(片手) | C25: ➁ | D25: ・/中/中 | F25: 227 | G25: 118 | H25: 192
A26: =ROW()-1 -> 25 | B26: 上膊抜(両手) | C26: ➁ | D26: ・/中/中
A27: =ROW()-1 -> 26 | B27: 押切抜 | C27: ➁ | D27: 対/中/中 | F27: 227 | G27: 120 | H27: 194
A28: =ROW()-1 -> 27 | B28: 切返抜(諸手) | C28: ➁ | D28: 対/下/一
A29: =ROW()-1 -> 28 | B29: 切返抜(片手) | C29: ➁ | D29: 対/下/一 | F29: 227 | G29: 112 | H29: 184
A30: =ROW()-1 -> 29 | B30: 打抜(片手) | C30: 二 | D30: 開/中/中 | E30: 外手 | F30: 228
A31: =ROW()-1 -> 30 | B31: 打抜(両手) | C31: 二 | D31: 対/中/中 | E31: 外手 | F31: 228
A32: =ROW()-1 -> 31 | B32: 三角抜 | C32: ➁ | D32: 対/下/中 | F32: 228 | G32: 114
A33: =ROW()-1 -> 32 | B33: 袖抜 | C33: ➀ | D33: ・/逆下/一 | F33: 229 | G33: 124
A34: =ROW()-1 -> 33 | B34: 襟抜 | C34: ➀ | D34: ・/逆下/中 | F34: 229 | G34: 132 | H34: 198
A35: =ROW()-1 -> 34 | B35: 足抜(二種) | C35: 四 | D35: 対/一/一 | E35: 廻蹴 | F35: 229

Sheet 龍華拳
B1: 龍華拳 | D1: 構/守/攻 | E1: 攻撃 | F1: 教範 | G1: はじめよう！ | H1: ー愛の価値
A2: =ROW()-1 -> 1 | B2: 逆小手 | C2: ➄ | D2: 対/中/中 | F2: 239 | G2: 90 | H2: 156
A3: =ROW()-1 -> 2 | B3: 諸手逆小手 | C3: 二 | D3: 開/中/中 | E3: 一背 | F3: 241
A4: =ROW()-1 -> 3 | B4: 合掌逆小手 | C4: 四 | D4: 対/中/中 | E4: 内手 | F4: 241
A5: =ROW()-1 -> 4 | B5: 逆合掌投(二種) | C5: 四 | D5: 対/開手/中 | E5: 手平 | F5: 242
A6: =ROW()-1 -> 5 | B6: 握返 | C6: 三 | D6: 直立/右前 | E6: 握手 | F6: 242
A7: =ROW()-1 -> 6 | B7: 逆手投 | C7: 二 | D7: 開/中/中 | E7: 内手 | F7: 242
A8: =ROW()-1 -> 7 | B8: 巻小手(片手) | C8: ➀ | D8: 対/中/中 | F8: 242
A9: =ROW()-1 -> 8 | B9: 巻小手(諸手) | C9: ➀ | D9: 対/中/中 | H9: 212
A10: =ROW()-1 -> 9 | B10: 下受蹴小手投 | C10: 二 | D10: 対/八/中 | E10: 中逆 | F10: 243 | H10: 214
A11: =ROW()-1 -> 10 | B11: 逆小手より裏返投 | C11: ➂ | D11: 対/中/中 | F11: 243
A12: =ROW()-1 -> 11 | B12: 巻込小手 | C12: 三 | D12: 対/下段/中 | E12: 捻上 | F12: 244
A13: =ROW()-1 -> 12 | B13: 龍投 | C13: 二 | D13: 開/中/中 | E13: 内手 | F13: 244
A14: =ROW()-1 -> 13 | B14: 外巻天秤 | C14: 二 | D14: 開/中/中 | E14: 内手 | F14: 245
A15: =ROW()-1 -> 14 | B15: 片手送小手 | C15: ➃ | D15: 開/中/中 | F15: 245 | H15: 166
A16: =ROW()-1 -> 15 | B16: 両手送小手 | C16: ➁ | D16: 対/中/中 | F16: 246 | G16: 98 | H16: 174
A17: =ROW()-1 -> 16 | B17: 諸手送小手投 | C17: 三 | D17: 開/中/中 | E17: 一背 | F17: 247
A18: =ROW()-1 -> 17 | B18: 諸手送小手より縛法 | C18: 二 | D18: 開/中/中 | E18: 一背
A19: =ROW()-1 -> 18 | B19: 送捕 | C19: ➁ | D19: 仕掛け | F19: 248
A20: =ROW()-1 -> 19 | B20: 木葉送 | C20: 三 | D20: 直立/開手 | E20: 仕掛 | F20: 248 | H20: 218
A21: =ROW()-1 -> 20 | B21: 送合掌(二種) | C21: 四 | D21: 開/開手/中 | E21: 手平 | F21: 248
A22: =ROW()-1 -> 21 | B22: 熊手返(両手) | C22: 四 | D22: 対/両開/中 | E22: 力比 | F22: 248
A23: =ROW()-1 -> 22 | B23: 熊手返(片手) | C23: 四 | D23: 対/両開/中 | E23: 力比
